[2017-10-19 19:09:28]---错误case个数为1!
[2017-10-19 19:09:28]---Traceback (most recent call last):
  File "D:\Beop-OnlineTest\interfaceTest\base_case\Base002expertContainerRun.py", line 40, in Test
    a.raiseError(error,self.testCaseID)
  File "D:\Beop-OnlineTest\interfaceTest\Methods\BeopTools.py", line 156, in raiseError
    assert 0,"\n".join(error)
AssertionError: 错误信息算法容器40.71.228.119:4000接口异常，请检查！

发送邮件出错,请检查!{'woody.wu@rnbtech.com.hk': (503, b"RCPT account isn't a local account")}
[2017-10-20 11:07:36]---错误case个数为1!
[2017-10-20 11:07:37]---Traceback (most recent call last):
  File "D:\Beop-OnlineTest\interfaceTest\calcPoint_Case\Calc044checkhistoryCumulant.py", line 58, in Test
    self.raiseError(message)
  File "D:\Beop-OnlineTest\interfaceTest\calcPoint_Case\Calc044checkhistoryCumulant.py", line 65, in raiseError
    assert 0,"错误信息：\n"+"\n".join(log)
AssertionError: 错误信息：
项目id为528的计算点如下：
RCS_Plant_Load_Accum累积量数据:{'2017-10-18 22:50:00': 4849693.221298483, '2017-10-18 22:55:00': 4849690.495424174}
qunlou_Plant_Cost_Accum累积量数据:{'2017-10-18 22:50:00': 3179825.647520829, '2017-10-18 22:55:00': 3179825.639947496}
qunlou_Plant_Load_Accum累积量数据:{'2017-10-17 20:25:00': 1526716.1398333332, '2017-10-17 20:30:00': 1526687.8291666666}
talou_CTGroup_Power_Accum累积量数据:{'2017-10-18 09:30:00': 9648.446666666647, '2017-10-18 09:35:00': 9647.246666666646}
talou_ChGroup_Power_Accum累积量数据:{'2017-10-19 20:35:00': 443139.44916666666, '2017-10-19 20:40:00': 443139.36583333334}
talou_Plant_Load_Accum累积量数据:{'2017-10-18 22:50:00': 3305085.3677937966, '2017-10-18 22:55:00': 3305082.5710861534}
项目id为120的计算点如下：
Accum_IceChargPGroupTotal101_GroupCost累积量数据:{'2017-10-17 17:25:00': 301808.9887500005, '2017-10-17 17:20:00': 301808.98875000054}
Accum_Plant_GroupCost累积量数据:{'2017-10-19 00:05:00': 2287650.339709661, '2017-10-19 00:00:00': 2287660.995959661}
Accum_Plant_GroupElecUse累积量数据:{'2017-10-19 00:05:00': 3079846.94, '2017-10-19 00:00:00': 3079878.19}
Accum_PumpGroupTotal001_GroupElecUse累积量数据:{'2017-10-19 00:05:00': 2611750.0, '2017-10-19 00:00:00': 2611781.25}
项目id为539的计算点如下：
xiqu_Plant_Load_Accum累积量数据:{'2017-10-17 11:40:00': 507823.15, '2017-10-17 11:35:00': 507842.15}
项目id为540的计算点如下：
Accum_RealTimePower_svr累积量数据:{'2017-10-17 21:10:00': 1923208.8493064197, '2017-10-17 21:05:00': 1923208.84930642}
qk01_Plant_Cost_Accum累积量数据:{'2017-10-19 10:50:00': 1812268.4507455148, '2017-10-19 10:45:00': 1812268.450745515}
qk01_Plant_Power_Accum累积量数据:{'2017-10-17 21:10:00': 1923208.8493064197, '2017-10-17 21:05:00': 1923208.84930642}
项目id为15的计算点如下：
Accum_B3F_Plant_Load累积量数据:{'2017-10-17 18:45:00': 333046.5846605991, '2017-10-17 18:50:00': 333046.52303754265}
Accum_RF_Plant_Load累积量数据:{'2017-10-18 17:55:00': 284853.55833333335, '2017-10-18 17:50:00': 284855.9166666667}
Accum_i6F_Plant_Load累积量数据:{'2017-10-17 18:45:00': 612014.8583333333, '2017-10-17 18:40:00': 612024.9416666667}

[2017-10-20 11:16:28]---错误case个数为1!
[2017-10-20 11:16:28]---Traceback (most recent call last):
  File "D:\Beop-OnlineTest\interfaceTest\calcPoint_Case\Calc044checkhistoryCumulant.py", line 58, in Test
    self.raiseError(message)
  File "D:\Beop-OnlineTest\interfaceTest\calcPoint_Case\Calc044checkhistoryCumulant.py", line 65, in raiseError
    assert 0,"错误信息：\n"+"\n".join(log)
AssertionError: 错误信息：
项目id为528的计算点如下：
RCS_Plant_Load_Accum累积量数据:{'2017-10-18 22:55:00': 4849690.495424174, '2017-10-18 22:50:00': 4849693.221298483}
qunlou_Plant_Cost_Accum累积量数据:{'2017-10-18 22:55:00': 3179825.639947496, '2017-10-18 22:50:00': 3179825.647520829}
qunlou_Plant_Load_Accum累积量数据:{'2017-10-17 20:25:00': 1526716.1398333332, '2017-10-17 20:30:00': 1526687.8291666666}
talou_CTGroup_Power_Accum累积量数据:{'2017-10-18 09:35:00': 9647.246666666646, '2017-10-18 09:30:00': 9648.446666666647}
talou_ChGroup_Power_Accum累积量数据:{'2017-10-19 20:35:00': 443139.44916666666, '2017-10-19 20:40:00': 443139.36583333334}
talou_Plant_Load_Accum累积量数据:{'2017-10-18 22:55:00': 3305082.5710861534, '2017-10-18 22:50:00': 3305085.3677937966}
项目id为120的计算点如下：
Accum_IceChargPGroupTotal101_GroupCost累积量数据:{'2017-10-17 17:20:00': 301808.98875000054, '2017-10-17 17:25:00': 301808.9887500005}
Accum_Plant_GroupCost累积量数据:{'2017-10-19 00:00:00': 2287660.995959661, '2017-10-19 00:05:00': 2287650.339709661}
Accum_Plant_GroupElecUse累积量数据:{'2017-10-19 00:00:00': 3079878.19, '2017-10-19 00:05:00': 3079846.94}
Accum_PumpGroupTotal001_GroupElecUse累积量数据:{'2017-10-19 00:00:00': 2611781.25, '2017-10-19 00:05:00': 2611750.0}
项目id为539的计算点如下：
xiqu_Plant_Load_Accum累积量数据:{'2017-10-17 11:40:00': 507823.15, '2017-10-17 11:35:00': 507842.15}
项目id为540的计算点如下：
Accum_RealTimePower_svr累积量数据:{'2017-10-17 21:05:00': 1923208.84930642, '2017-10-17 21:10:00': 1923208.8493064197}
qk01_Plant_Cost_Accum累积量数据:{'2017-10-19 10:45:00': 1812268.450745515, '2017-10-19 10:50:00': 1812268.4507455148}
qk01_Plant_Power_Accum累积量数据:{'2017-10-17 21:05:00': 1923208.84930642, '2017-10-17 21:10:00': 1923208.8493064197}
项目id为15的计算点如下：
Accum_B3F_Plant_Load累积量数据:{'2017-10-17 18:50:00': 333046.52303754265, '2017-10-17 18:45:00': 333046.5846605991}
Accum_RF_Plant_Load累积量数据:{'2017-10-18 17:50:00': 284855.9166666667, '2017-10-18 17:55:00': 284853.55833333335}
Accum_i6F_Plant_Load累积量数据:{'2017-10-17 18:40:00': 612024.9416666667, '2017-10-17 18:45:00': 612014.8583333333}

[2017-10-20 11:17:13]---错误case个数为1!
[2017-10-20 11:17:13]---Traceback (most recent call last):
  File "D:\Beop-OnlineTest\interfaceTest\calcPoint_Case\Calc044checkhistoryCumulant.py", line 58, in Test
    self.raiseError(message)
  File "D:\Beop-OnlineTest\interfaceTest\calcPoint_Case\Calc044checkhistoryCumulant.py", line 65, in raiseError
    assert 0,"错误信息：\n"+"\n".join(log)
AssertionError: 错误信息：
项目id为528的计算点如下：
RCS_Plant_Load_Accum累积量数据:{'2017-10-18 22:50:00': 4849693.221298483, '2017-10-18 22:55:00': 4849690.495424174}
qunlou_Plant_Cost_Accum累积量数据:{'2017-10-18 22:50:00': 3179825.647520829, '2017-10-18 22:55:00': 3179825.639947496}
qunlou_Plant_Load_Accum累积量数据:{'2017-10-17 20:25:00': 1526716.1398333332, '2017-10-17 20:30:00': 1526687.8291666666}
talou_CTGroup_Power_Accum累积量数据:{'2017-10-18 09:30:00': 9648.446666666647, '2017-10-18 09:35:00': 9647.246666666646}
talou_ChGroup_Power_Accum累积量数据:{'2017-10-19 20:35:00': 443139.44916666666, '2017-10-19 20:40:00': 443139.36583333334}
talou_Plant_Load_Accum累积量数据:{'2017-10-18 22:50:00': 3305085.3677937966, '2017-10-18 22:55:00': 3305082.5710861534}
项目id为120的计算点如下：
Accum_IceChargPGroupTotal101_GroupCost累积量数据:{'2017-10-17 17:20:00': 301808.98875000054, '2017-10-17 17:25:00': 301808.9887500005}
Accum_Plant_GroupCost累积量数据:{'2017-10-19 00:00:00': 2287660.995959661, '2017-10-19 00:05:00': 2287650.339709661}
Accum_Plant_GroupElecUse累积量数据:{'2017-10-19 00:00:00': 3079878.19, '2017-10-19 00:05:00': 3079846.94}
Accum_PumpGroupTotal001_GroupElecUse累积量数据:{'2017-10-19 00:00:00': 2611781.25, '2017-10-19 00:05:00': 2611750.0}
项目id为539的计算点如下：
xiqu_Plant_Load_Accum累积量数据:{'2017-10-17 11:40:00': 507823.15, '2017-10-17 11:35:00': 507842.15}
项目id为540的计算点如下：
Accum_RealTimePower_svr累积量数据:{'2017-10-17 21:10:00': 1923208.8493064197, '2017-10-17 21:05:00': 1923208.84930642}
qk01_Plant_Cost_Accum累积量数据:{'2017-10-19 10:45:00': 1812268.450745515, '2017-10-19 10:50:00': 1812268.4507455148}
qk01_Plant_Power_Accum累积量数据:{'2017-10-17 21:10:00': 1923208.8493064197, '2017-10-17 21:05:00': 1923208.84930642}
项目id为15的计算点如下：
Accum_B3F_Plant_Load累积量数据:{'2017-10-17 18:45:00': 333046.5846605991, '2017-10-17 18:50:00': 333046.52303754265}
Accum_RF_Plant_Load累积量数据:{'2017-10-18 17:50:00': 284855.9166666667, '2017-10-18 17:55:00': 284853.55833333335}
Accum_i6F_Plant_Load累积量数据:{'2017-10-17 18:45:00': 612014.8583333333, '2017-10-17 18:40:00': 612024.9416666667}

[2017-10-20 11:18:18]---错误case个数为1!
[2017-10-20 11:18:18]---Traceback (most recent call last):
  File "D:\Beop-OnlineTest\interfaceTest\calcPoint_Case\Calc044checkhistoryCumulant.py", line 58, in Test
    self.raiseError(message)
  File "D:\Beop-OnlineTest\interfaceTest\calcPoint_Case\Calc044checkhistoryCumulant.py", line 65, in raiseError
    assert 0,"错误信息：\n"+"\n".join(log)
AssertionError: 错误信息：
项目id为528的计算点如下：
RCS_Plant_Load_Accum累积量数据:{'2017-10-18 22:55:00': 4849690.495424174, '2017-10-18 22:50:00': 4849693.221298483}
qunlou_Plant_Cost_Accum累积量数据:{'2017-10-18 22:55:00': 3179825.639947496, '2017-10-18 22:50:00': 3179825.647520829}
qunlou_Plant_Load_Accum累积量数据:{'2017-10-17 20:30:00': 1526687.8291666666, '2017-10-17 20:25:00': 1526716.1398333332}
talou_CTGroup_Power_Accum累积量数据:{'2017-10-18 09:35:00': 9647.246666666646, '2017-10-18 09:30:00': 9648.446666666647}
talou_ChGroup_Power_Accum累积量数据:{'2017-10-19 20:35:00': 443139.44916666666, '2017-10-19 20:40:00': 443139.36583333334}
talou_Plant_Load_Accum累积量数据:{'2017-10-18 22:55:00': 3305082.5710861534, '2017-10-18 22:50:00': 3305085.3677937966}
项目id为120的计算点如下：
Accum_IceChargPGroupTotal101_GroupCost累积量数据:{'2017-10-17 17:25:00': 301808.9887500005, '2017-10-17 17:20:00': 301808.98875000054}
Accum_Plant_GroupCost累积量数据:{'2017-10-19 00:00:00': 2287660.995959661, '2017-10-19 00:05:00': 2287650.339709661}
Accum_Plant_GroupElecUse累积量数据:{'2017-10-19 00:00:00': 3079878.19, '2017-10-19 00:05:00': 3079846.94}
Accum_PumpGroupTotal001_GroupElecUse累积量数据:{'2017-10-19 00:00:00': 2611781.25, '2017-10-19 00:05:00': 2611750.0}
项目id为539的计算点如下：
xiqu_Plant_Load_Accum累积量数据:{'2017-10-17 11:35:00': 507842.15, '2017-10-17 11:40:00': 507823.15}
项目id为540的计算点如下：
Accum_RealTimePower_svr累积量数据:{'2017-10-17 21:10:00': 1923208.8493064197, '2017-10-17 21:05:00': 1923208.84930642}
qk01_Plant_Cost_Accum累积量数据:{'2017-10-19 10:50:00': 1812268.4507455148, '2017-10-19 10:45:00': 1812268.450745515}
qk01_Plant_Power_Accum累积量数据:{'2017-10-17 21:10:00': 1923208.8493064197, '2017-10-17 21:05:00': 1923208.84930642}
项目id为15的计算点如下：
Accum_B3F_Plant_Load累积量数据:{'2017-10-17 18:50:00': 333046.52303754265, '2017-10-17 18:45:00': 333046.5846605991}
Accum_RF_Plant_Load累积量数据:{'2017-10-18 17:55:00': 284853.55833333335, '2017-10-18 17:50:00': 284855.9166666667}
Accum_i6F_Plant_Load累积量数据:{'2017-10-17 18:45:00': 612014.8583333333, '2017-10-17 18:40:00': 612024.9416666667}

[2017-10-20 11:19:17]---错误case个数为1!
[2017-10-20 11:19:17]---Traceback (most recent call last):
  File "D:\Beop-OnlineTest\interfaceTest\calcPoint_Case\Calc044checkhistoryCumulant.py", line 58, in Test
    self.raiseError(message)
  File "D:\Beop-OnlineTest\interfaceTest\calcPoint_Case\Calc044checkhistoryCumulant.py", line 65, in raiseError
    assert 0,"错误信息：\n"+"\n".join(log)
AssertionError: 错误信息：
项目id为528的计算点如下：
RCS_Plant_Load_Accum累积量数据:{'2017-10-18 22:55:00': 4849690.495424174, '2017-10-18 22:50:00': 4849693.221298483}
qunlou_Plant_Cost_Accum累积量数据:{'2017-10-18 22:55:00': 3179825.639947496, '2017-10-18 22:50:00': 3179825.647520829}
qunlou_Plant_Load_Accum累积量数据:{'2017-10-17 20:30:00': 1526687.8291666666, '2017-10-17 20:25:00': 1526716.1398333332}
talou_CTGroup_Power_Accum累积量数据:{'2017-10-18 09:35:00': 9647.246666666646, '2017-10-18 09:30:00': 9648.446666666647}
talou_ChGroup_Power_Accum累积量数据:{'2017-10-19 20:35:00': 443139.44916666666, '2017-10-19 20:40:00': 443139.36583333334}
talou_Plant_Load_Accum累积量数据:{'2017-10-18 22:55:00': 3305082.5710861534, '2017-10-18 22:50:00': 3305085.3677937966}
项目id为120的计算点如下：
Accum_IceChargPGroupTotal101_GroupCost累积量数据:{'2017-10-17 17:25:00': 301808.9887500005, '2017-10-17 17:20:00': 301808.98875000054}
Accum_Plant_GroupCost累积量数据:{'2017-10-19 00:05:00': 2287650.339709661, '2017-10-19 00:00:00': 2287660.995959661}
Accum_Plant_GroupElecUse累积量数据:{'2017-10-19 00:05:00': 3079846.94, '2017-10-19 00:00:00': 3079878.19}
Accum_PumpGroupTotal001_GroupElecUse累积量数据:{'2017-10-19 00:05:00': 2611750.0, '2017-10-19 00:00:00': 2611781.25}
项目id为539的计算点如下：
xiqu_Plant_Load_Accum累积量数据:{'2017-10-17 11:35:00': 507842.15, '2017-10-17 11:40:00': 507823.15}
项目id为540的计算点如下：
Accum_RealTimePower_svr累积量数据:{'2017-10-17 21:05:00': 1923208.84930642, '2017-10-17 21:10:00': 1923208.8493064197}
qk01_Plant_Cost_Accum累积量数据:{'2017-10-19 10:45:00': 1812268.450745515, '2017-10-19 10:50:00': 1812268.4507455148}
qk01_Plant_Power_Accum累积量数据:{'2017-10-17 21:05:00': 1923208.84930642, '2017-10-17 21:10:00': 1923208.8493064197}
项目id为15的计算点如下：
Accum_B3F_Plant_Load累积量数据:{'2017-10-17 18:50:00': 333046.52303754265, '2017-10-17 18:45:00': 333046.5846605991}
Accum_RF_Plant_Load累积量数据:{'2017-10-18 17:50:00': 284855.9166666667, '2017-10-18 17:55:00': 284853.55833333335}
Accum_i6F_Plant_Load累积量数据:{'2017-10-17 18:45:00': 612014.8583333333, '2017-10-17 18:40:00': 612024.9416666667}

[2017-10-20 11:21:07]---错误case个数为1!
[2017-10-20 11:21:07]---Traceback (most recent call last):
  File "D:\Beop-OnlineTest\interfaceTest\calcPoint_Case\Calc044checkhistoryCumulant.py", line 58, in Test
    self.raiseError(message)
  File "D:\Beop-OnlineTest\interfaceTest\calcPoint_Case\Calc044checkhistoryCumulant.py", line 65, in raiseError
    assert 0,"错误信息：\n"+"\n".join(log)
AssertionError: 错误信息：
项目id为528的计算点如下：
RCS_Plant_Load_Accum累积量数据:{'2017-10-18 22:50:00': 4849693.221298483, '2017-10-18 22:55:00': 4849690.495424174}
qunlou_Plant_Cost_Accum累积量数据:{'2017-10-18 22:50:00': 3179825.647520829, '2017-10-18 22:55:00': 3179825.639947496}
qunlou_Plant_Load_Accum累积量数据:{'2017-10-17 20:25:00': 1526716.1398333332, '2017-10-17 20:30:00': 1526687.8291666666}
talou_CTGroup_Power_Accum累积量数据:{'2017-10-18 09:35:00': 9647.246666666646, '2017-10-18 09:30:00': 9648.446666666647}
talou_ChGroup_Power_Accum累积量数据:{'2017-10-19 20:35:00': 443139.44916666666, '2017-10-19 20:40:00': 443139.36583333334}
talou_Plant_Load_Accum累积量数据:{'2017-10-18 22:50:00': 3305085.3677937966, '2017-10-18 22:55:00': 3305082.5710861534}
项目id为120的计算点如下：
Accum_IceChargPGroupTotal101_GroupCost累积量数据:{'2017-10-17 17:20:00': 301808.98875000054, '2017-10-17 17:25:00': 301808.9887500005}
Accum_Plant_GroupCost累积量数据:{'2017-10-19 00:00:00': 2287660.995959661, '2017-10-19 00:05:00': 2287650.339709661}
Accum_Plant_GroupElecUse累积量数据:{'2017-10-19 00:00:00': 3079878.19, '2017-10-19 00:05:00': 3079846.94}
Accum_PumpGroupTotal001_GroupElecUse累积量数据:{'2017-10-19 00:00:00': 2611781.25, '2017-10-19 00:05:00': 2611750.0}
项目id为539的计算点如下：
xiqu_Plant_Load_Accum累积量数据:{'2017-10-17 11:35:00': 507842.15, '2017-10-17 11:40:00': 507823.15}
项目id为540的计算点如下：
Accum_RealTimePower_svr累积量数据:{'2017-10-17 21:05:00': 1923208.84930642, '2017-10-17 21:10:00': 1923208.8493064197}
qk01_Plant_Cost_Accum累积量数据:{'2017-10-19 10:50:00': 1812268.4507455148, '2017-10-19 10:45:00': 1812268.450745515}
qk01_Plant_Power_Accum累积量数据:{'2017-10-17 21:05:00': 1923208.84930642, '2017-10-17 21:10:00': 1923208.8493064197}
项目id为15的计算点如下：
Accum_B3F_Plant_Load累积量数据:{'2017-10-17 18:50:00': 333046.52303754265, '2017-10-17 18:45:00': 333046.5846605991}
Accum_RF_Plant_Load累积量数据:{'2017-10-18 17:55:00': 284853.55833333335, '2017-10-18 17:50:00': 284855.9166666667}
Accum_i6F_Plant_Load累积量数据:{'2017-10-17 18:45:00': 612014.8583333333, '2017-10-17 18:40:00': 612024.9416666667}

[2017-10-20 11:21:19]---邮箱为空!
[2017-10-20 11:21:36]---错误case个数为1!
[2017-10-20 11:21:36]---Traceback (most recent call last):
  File "D:\Beop-OnlineTest\interfaceTest\calcPoint_Case\Calc044checkhistoryCumulant.py", line 58, in Test
    self.raiseError(message)
  File "D:\Beop-OnlineTest\interfaceTest\calcPoint_Case\Calc044checkhistoryCumulant.py", line 65, in raiseError
    assert 0,"错误信息：\n"+"\n".join(log)
AssertionError: 错误信息：
项目id为528的计算点如下：
RCS_Plant_Load_Accum累积量数据:{'2017-10-18 22:50:00': 4849693.221298483, '2017-10-18 22:55:00': 4849690.495424174}
qunlou_Plant_Cost_Accum累积量数据:{'2017-10-18 22:50:00': 3179825.647520829, '2017-10-18 22:55:00': 3179825.639947496}
qunlou_Plant_Load_Accum累积量数据:{'2017-10-17 20:25:00': 1526716.1398333332, '2017-10-17 20:30:00': 1526687.8291666666}
talou_CTGroup_Power_Accum累积量数据:{'2017-10-18 09:35:00': 9647.246666666646, '2017-10-18 09:30:00': 9648.446666666647}
talou_ChGroup_Power_Accum累积量数据:{'2017-10-19 20:35:00': 443139.44916666666, '2017-10-19 20:40:00': 443139.36583333334}
talou_Plant_Load_Accum累积量数据:{'2017-10-18 22:50:00': 3305085.3677937966, '2017-10-18 22:55:00': 3305082.5710861534}
项目id为120的计算点如下：
Accum_IceChargPGroupTotal101_GroupCost累积量数据:{'2017-10-17 17:20:00': 301808.98875000054, '2017-10-17 17:25:00': 301808.9887500005}
Accum_Plant_GroupCost累积量数据:{'2017-10-19 00:00:00': 2287660.995959661, '2017-10-19 00:05:00': 2287650.339709661}
Accum_Plant_GroupElecUse累积量数据:{'2017-10-19 00:00:00': 3079878.19, '2017-10-19 00:05:00': 3079846.94}
Accum_PumpGroupTotal001_GroupElecUse累积量数据:{'2017-10-19 00:00:00': 2611781.25, '2017-10-19 00:05:00': 2611750.0}
项目id为539的计算点如下：
xiqu_Plant_Load_Accum累积量数据:{'2017-10-17 11:35:00': 507842.15, '2017-10-17 11:40:00': 507823.15}
项目id为540的计算点如下：
Accum_RealTimePower_svr累积量数据:{'2017-10-17 21:05:00': 1923208.84930642, '2017-10-17 21:10:00': 1923208.8493064197}
qk01_Plant_Cost_Accum累积量数据:{'2017-10-19 10:50:00': 1812268.4507455148, '2017-10-19 10:45:00': 1812268.450745515}
qk01_Plant_Power_Accum累积量数据:{'2017-10-17 21:05:00': 1923208.84930642, '2017-10-17 21:10:00': 1923208.8493064197}
项目id为15的计算点如下：
Accum_B3F_Plant_Load累积量数据:{'2017-10-17 18:50:00': 333046.52303754265, '2017-10-17 18:45:00': 333046.5846605991}
Accum_RF_Plant_Load累积量数据:{'2017-10-18 17:55:00': 284853.55833333335, '2017-10-18 17:50:00': 284855.9166666667}
Accum_i6F_Plant_Load累积量数据:{'2017-10-17 18:45:00': 612014.8583333333, '2017-10-17 18:40:00': 612024.9416666667}

[2017-10-20 11:22:31]---错误case个数为1!
[2017-10-20 11:22:31]---Traceback (most recent call last):
  File "D:\Beop-OnlineTest\interfaceTest\calcPoint_Case\Calc044checkhistoryCumulant.py", line 58, in Test
    self.raiseError(message)
  File "D:\Beop-OnlineTest\interfaceTest\calcPoint_Case\Calc044checkhistoryCumulant.py", line 65, in raiseError
    assert 0,"错误信息：\n"+"\n".join(log)
AssertionError: 错误信息：
项目id为528的计算点如下：
RCS_Plant_Load_Accum累积量数据:{'2017-10-18 22:55:00': 4849690.495424174, '2017-10-18 22:50:00': 4849693.221298483}
qunlou_Plant_Cost_Accum累积量数据:{'2017-10-18 22:55:00': 3179825.639947496, '2017-10-18 22:50:00': 3179825.647520829}
qunlou_Plant_Load_Accum累积量数据:{'2017-10-17 20:30:00': 1526687.8291666666, '2017-10-17 20:25:00': 1526716.1398333332}
talou_CTGroup_Power_Accum累积量数据:{'2017-10-18 09:30:00': 9648.446666666647, '2017-10-18 09:35:00': 9647.246666666646}
talou_ChGroup_Power_Accum累积量数据:{'2017-10-19 20:40:00': 443139.36583333334, '2017-10-19 20:35:00': 443139.44916666666}
talou_Plant_Load_Accum累积量数据:{'2017-10-18 22:55:00': 3305082.5710861534, '2017-10-18 22:50:00': 3305085.3677937966}
项目id为120的计算点如下：
Accum_IceChargPGroupTotal101_GroupCost累积量数据:{'2017-10-17 17:20:00': 301808.98875000054, '2017-10-17 17:25:00': 301808.9887500005}
Accum_Plant_GroupCost累积量数据:{'2017-10-19 00:05:00': 2287650.339709661, '2017-10-19 00:00:00': 2287660.995959661}
Accum_Plant_GroupElecUse累积量数据:{'2017-10-19 00:05:00': 3079846.94, '2017-10-19 00:00:00': 3079878.19}
Accum_PumpGroupTotal001_GroupElecUse累积量数据:{'2017-10-19 00:05:00': 2611750.0, '2017-10-19 00:00:00': 2611781.25}
项目id为539的计算点如下：
xiqu_Plant_Load_Accum累积量数据:{'2017-10-17 11:40:00': 507823.15, '2017-10-17 11:35:00': 507842.15}
项目id为540的计算点如下：
Accum_RealTimePower_svr累积量数据:{'2017-10-17 21:10:00': 1923208.8493064197, '2017-10-17 21:05:00': 1923208.84930642}
qk01_Plant_Cost_Accum累积量数据:{'2017-10-19 10:50:00': 1812268.4507455148, '2017-10-19 10:45:00': 1812268.450745515}
qk01_Plant_Power_Accum累积量数据:{'2017-10-17 21:10:00': 1923208.8493064197, '2017-10-17 21:05:00': 1923208.84930642}
项目id为15的计算点如下：
Accum_B3F_Plant_Load累积量数据:{'2017-10-17 18:45:00': 333046.5846605991, '2017-10-17 18:50:00': 333046.52303754265}
Accum_RF_Plant_Load累积量数据:{'2017-10-18 17:55:00': 284853.55833333335, '2017-10-18 17:50:00': 284855.9166666667}
Accum_i6F_Plant_Load累积量数据:{'2017-10-17 18:45:00': 612014.8583333333, '2017-10-17 18:40:00': 612024.9416666667}

[2017-10-20 11:22:33]---邮箱为空!
[2017-10-20 11:22:45]---错误case个数为1!
[2017-10-20 11:22:45]---Traceback (most recent call last):
  File "D:\Beop-OnlineTest\interfaceTest\calcPoint_Case\Calc044checkhistoryCumulant.py", line 58, in Test
    self.raiseError(message)
  File "D:\Beop-OnlineTest\interfaceTest\calcPoint_Case\Calc044checkhistoryCumulant.py", line 65, in raiseError
    assert 0,"错误信息：\n"+"\n".join(log)
AssertionError: 错误信息：
项目id为528的计算点如下：
RCS_Plant_Load_Accum累积量数据:{'2017-10-18 22:55:00': 4849690.495424174, '2017-10-18 22:50:00': 4849693.221298483}
qunlou_Plant_Cost_Accum累积量数据:{'2017-10-18 22:55:00': 3179825.639947496, '2017-10-18 22:50:00': 3179825.647520829}
qunlou_Plant_Load_Accum累积量数据:{'2017-10-17 20:30:00': 1526687.8291666666, '2017-10-17 20:25:00': 1526716.1398333332}
talou_CTGroup_Power_Accum累积量数据:{'2017-10-18 09:30:00': 9648.446666666647, '2017-10-18 09:35:00': 9647.246666666646}
talou_ChGroup_Power_Accum累积量数据:{'2017-10-19 20:40:00': 443139.36583333334, '2017-10-19 20:35:00': 443139.44916666666}
talou_Plant_Load_Accum累积量数据:{'2017-10-18 22:55:00': 3305082.5710861534, '2017-10-18 22:50:00': 3305085.3677937966}
项目id为120的计算点如下：
Accum_IceChargPGroupTotal101_GroupCost累积量数据:{'2017-10-17 17:20:00': 301808.98875000054, '2017-10-17 17:25:00': 301808.9887500005}
Accum_Plant_GroupCost累积量数据:{'2017-10-19 00:05:00': 2287650.339709661, '2017-10-19 00:00:00': 2287660.995959661}
Accum_Plant_GroupElecUse累积量数据:{'2017-10-19 00:05:00': 3079846.94, '2017-10-19 00:00:00': 3079878.19}
Accum_PumpGroupTotal001_GroupElecUse累积量数据:{'2017-10-19 00:05:00': 2611750.0, '2017-10-19 00:00:00': 2611781.25}
项目id为539的计算点如下：
xiqu_Plant_Load_Accum累积量数据:{'2017-10-17 11:40:00': 507823.15, '2017-10-17 11:35:00': 507842.15}
项目id为540的计算点如下：
Accum_RealTimePower_svr累积量数据:{'2017-10-17 21:10:00': 1923208.8493064197, '2017-10-17 21:05:00': 1923208.84930642}
qk01_Plant_Cost_Accum累积量数据:{'2017-10-19 10:50:00': 1812268.4507455148, '2017-10-19 10:45:00': 1812268.450745515}
qk01_Plant_Power_Accum累积量数据:{'2017-10-17 21:10:00': 1923208.8493064197, '2017-10-17 21:05:00': 1923208.84930642}
项目id为15的计算点如下：
Accum_B3F_Plant_Load累积量数据:{'2017-10-17 18:45:00': 333046.5846605991, '2017-10-17 18:50:00': 333046.52303754265}
Accum_RF_Plant_Load累积量数据:{'2017-10-18 17:55:00': 284853.55833333335, '2017-10-18 17:50:00': 284855.9166666667}
Accum_i6F_Plant_Load累积量数据:{'2017-10-17 18:45:00': 612014.8583333333, '2017-10-17 18:40:00': 612024.9416666667}

[2017-10-20 11:22:56]---邮箱为空!
[2017-10-20 11:23:11]---错误case个数为1!
[2017-10-20 11:23:11]---Traceback (most recent call last):
  File "D:\Beop-OnlineTest\interfaceTest\calcPoint_Case\Calc044checkhistoryCumulant.py", line 58, in Test
    self.raiseError(message)
  File "D:\Beop-OnlineTest\interfaceTest\calcPoint_Case\Calc044checkhistoryCumulant.py", line 65, in raiseError
    assert 0,"错误信息：\n"+"\n".join(log)
AssertionError: 错误信息：
项目id为528的计算点如下：
RCS_Plant_Load_Accum累积量数据:{'2017-10-18 22:55:00': 4849690.495424174, '2017-10-18 22:50:00': 4849693.221298483}
qunlou_Plant_Cost_Accum累积量数据:{'2017-10-18 22:55:00': 3179825.639947496, '2017-10-18 22:50:00': 3179825.647520829}
qunlou_Plant_Load_Accum累积量数据:{'2017-10-17 20:30:00': 1526687.8291666666, '2017-10-17 20:25:00': 1526716.1398333332}
talou_CTGroup_Power_Accum累积量数据:{'2017-10-18 09:30:00': 9648.446666666647, '2017-10-18 09:35:00': 9647.246666666646}
talou_ChGroup_Power_Accum累积量数据:{'2017-10-19 20:40:00': 443139.36583333334, '2017-10-19 20:35:00': 443139.44916666666}
talou_Plant_Load_Accum累积量数据:{'2017-10-18 22:55:00': 3305082.5710861534, '2017-10-18 22:50:00': 3305085.3677937966}
项目id为120的计算点如下：
Accum_IceChargPGroupTotal101_GroupCost累积量数据:{'2017-10-17 17:20:00': 301808.98875000054, '2017-10-17 17:25:00': 301808.9887500005}
Accum_Plant_GroupCost累积量数据:{'2017-10-19 00:05:00': 2287650.339709661, '2017-10-19 00:00:00': 2287660.995959661}
Accum_Plant_GroupElecUse累积量数据:{'2017-10-19 00:05:00': 3079846.94, '2017-10-19 00:00:00': 3079878.19}
Accum_PumpGroupTotal001_GroupElecUse累积量数据:{'2017-10-19 00:05:00': 2611750.0, '2017-10-19 00:00:00': 2611781.25}
项目id为539的计算点如下：
xiqu_Plant_Load_Accum累积量数据:{'2017-10-17 11:40:00': 507823.15, '2017-10-17 11:35:00': 507842.15}
项目id为540的计算点如下：
Accum_RealTimePower_svr累积量数据:{'2017-10-17 21:10:00': 1923208.8493064197, '2017-10-17 21:05:00': 1923208.84930642}
qk01_Plant_Cost_Accum累积量数据:{'2017-10-19 10:50:00': 1812268.4507455148, '2017-10-19 10:45:00': 1812268.450745515}
qk01_Plant_Power_Accum累积量数据:{'2017-10-17 21:10:00': 1923208.8493064197, '2017-10-17 21:05:00': 1923208.84930642}
项目id为15的计算点如下：
Accum_B3F_Plant_Load累积量数据:{'2017-10-17 18:45:00': 333046.5846605991, '2017-10-17 18:50:00': 333046.52303754265}
Accum_RF_Plant_Load累积量数据:{'2017-10-18 17:55:00': 284853.55833333335, '2017-10-18 17:50:00': 284855.9166666667}
Accum_i6F_Plant_Load累积量数据:{'2017-10-17 18:45:00': 612014.8583333333, '2017-10-17 18:40:00': 612024.9416666667}

[2017-10-20 11:24:04]---邮箱为空!
[2017-10-20 11:24:15]---错误case个数为1!
[2017-10-20 11:24:15]---Traceback (most recent call last):
  File "D:\Beop-OnlineTest\interfaceTest\calcPoint_Case\Calc044checkhistoryCumulant.py", line 58, in Test
    self.raiseError(message)
  File "D:\Beop-OnlineTest\interfaceTest\calcPoint_Case\Calc044checkhistoryCumulant.py", line 65, in raiseError
    assert 0,"错误信息：\n"+"\n".join(log)
AssertionError: 错误信息：
项目id为528的计算点如下：
RCS_Plant_Load_Accum累积量数据:{'2017-10-18 22:55:00': 4849690.495424174, '2017-10-18 22:50:00': 4849693.221298483}
qunlou_Plant_Cost_Accum累积量数据:{'2017-10-18 22:55:00': 3179825.639947496, '2017-10-18 22:50:00': 3179825.647520829}
qunlou_Plant_Load_Accum累积量数据:{'2017-10-17 20:30:00': 1526687.8291666666, '2017-10-17 20:25:00': 1526716.1398333332}
talou_CTGroup_Power_Accum累积量数据:{'2017-10-18 09:30:00': 9648.446666666647, '2017-10-18 09:35:00': 9647.246666666646}
talou_ChGroup_Power_Accum累积量数据:{'2017-10-19 20:40:00': 443139.36583333334, '2017-10-19 20:35:00': 443139.44916666666}
talou_Plant_Load_Accum累积量数据:{'2017-10-18 22:55:00': 3305082.5710861534, '2017-10-18 22:50:00': 3305085.3677937966}
项目id为120的计算点如下：
Accum_IceChargPGroupTotal101_GroupCost累积量数据:{'2017-10-17 17:20:00': 301808.98875000054, '2017-10-17 17:25:00': 301808.9887500005}
Accum_Plant_GroupCost累积量数据:{'2017-10-19 00:05:00': 2287650.339709661, '2017-10-19 00:00:00': 2287660.995959661}
Accum_Plant_GroupElecUse累积量数据:{'2017-10-19 00:05:00': 3079846.94, '2017-10-19 00:00:00': 3079878.19}
Accum_PumpGroupTotal001_GroupElecUse累积量数据:{'2017-10-19 00:05:00': 2611750.0, '2017-10-19 00:00:00': 2611781.25}
项目id为539的计算点如下：
xiqu_Plant_Load_Accum累积量数据:{'2017-10-17 11:40:00': 507823.15, '2017-10-17 11:35:00': 507842.15}
项目id为540的计算点如下：
Accum_RealTimePower_svr累积量数据:{'2017-10-17 21:10:00': 1923208.8493064197, '2017-10-17 21:05:00': 1923208.84930642}
qk01_Plant_Cost_Accum累积量数据:{'2017-10-19 10:50:00': 1812268.4507455148, '2017-10-19 10:45:00': 1812268.450745515}
qk01_Plant_Power_Accum累积量数据:{'2017-10-17 21:10:00': 1923208.8493064197, '2017-10-17 21:05:00': 1923208.84930642}
项目id为15的计算点如下：
Accum_B3F_Plant_Load累积量数据:{'2017-10-17 18:45:00': 333046.5846605991, '2017-10-17 18:50:00': 333046.52303754265}
Accum_RF_Plant_Load累积量数据:{'2017-10-18 17:55:00': 284853.55833333335, '2017-10-18 17:50:00': 284855.9166666667}
Accum_i6F_Plant_Load累积量数据:{'2017-10-17 18:45:00': 612014.8583333333, '2017-10-17 18:40:00': 612024.9416666667}

[2017-10-20 11:28:07]---错误case个数为1!
[2017-10-20 11:28:07]---Traceback (most recent call last):
  File "D:\Beop-OnlineTest\interfaceTest\calcPoint_Case\Calc044checkhistoryCumulant.py", line 58, in Test
    self.raiseError(message)
  File "D:\Beop-OnlineTest\interfaceTest\calcPoint_Case\Calc044checkhistoryCumulant.py", line 65, in raiseError
    assert 0,"错误信息：\n"+"\n".join(log)
AssertionError: 错误信息：
项目id为528的计算点如下：
RCS_Plant_Load_Accum累积量数据:{'2017-10-18 22:50:00': 4849693.221298483, '2017-10-18 22:55:00': 4849690.495424174}
qunlou_Plant_Cost_Accum累积量数据:{'2017-10-18 22:50:00': 3179825.647520829, '2017-10-18 22:55:00': 3179825.639947496}
qunlou_Plant_Load_Accum累积量数据:{'2017-10-17 20:25:00': 1526716.1398333332, '2017-10-17 20:30:00': 1526687.8291666666}
talou_CTGroup_Power_Accum累积量数据:{'2017-10-18 09:35:00': 9647.246666666646, '2017-10-18 09:30:00': 9648.446666666647}
talou_ChGroup_Power_Accum累积量数据:{'2017-10-19 20:40:00': 443139.36583333334, '2017-10-19 20:35:00': 443139.44916666666}
talou_Plant_Load_Accum累积量数据:{'2017-10-18 22:50:00': 3305085.3677937966, '2017-10-18 22:55:00': 3305082.5710861534}
项目id为120的计算点如下：
Accum_IceChargPGroupTotal101_GroupCost累积量数据:{'2017-10-17 17:25:00': 301808.9887500005, '2017-10-17 17:20:00': 301808.98875000054}
Accum_Plant_GroupCost累积量数据:{'2017-10-19 00:05:00': 2287650.339709661, '2017-10-19 00:00:00': 2287660.995959661}
Accum_Plant_GroupElecUse累积量数据:{'2017-10-19 00:05:00': 3079846.94, '2017-10-19 00:00:00': 3079878.19}
Accum_PumpGroupTotal001_GroupElecUse累积量数据:{'2017-10-19 00:05:00': 2611750.0, '2017-10-19 00:00:00': 2611781.25}
项目id为539的计算点如下：
xiqu_Plant_Load_Accum累积量数据:{'2017-10-17 11:40:00': 507823.15, '2017-10-17 11:35:00': 507842.15}
项目id为540的计算点如下：
Accum_RealTimePower_svr累积量数据:{'2017-10-17 21:10:00': 1923208.8493064197, '2017-10-17 21:05:00': 1923208.84930642}
qk01_Plant_Cost_Accum累积量数据:{'2017-10-19 10:45:00': 1812268.450745515, '2017-10-19 10:50:00': 1812268.4507455148}
qk01_Plant_Power_Accum累积量数据:{'2017-10-17 21:10:00': 1923208.8493064197, '2017-10-17 21:05:00': 1923208.84930642}
项目id为15的计算点如下：
Accum_B3F_Plant_Load累积量数据:{'2017-10-17 18:45:00': 333046.5846605991, '2017-10-17 18:50:00': 333046.52303754265}
Accum_RF_Plant_Load累积量数据:{'2017-10-18 17:55:00': 284853.55833333335, '2017-10-18 17:50:00': 284855.9166666667}
Accum_i6F_Plant_Load累积量数据:{'2017-10-17 18:45:00': 612014.8583333333, '2017-10-17 18:40:00': 612024.9416666667}

[2017-10-20 11:28:16]---邮箱为空!
[2017-10-20 11:28:27]---错误case个数为1!
[2017-10-20 11:28:27]---Traceback (most recent call last):
  File "D:\Beop-OnlineTest\interfaceTest\calcPoint_Case\Calc044checkhistoryCumulant.py", line 58, in Test
    self.raiseError(message)
  File "D:\Beop-OnlineTest\interfaceTest\calcPoint_Case\Calc044checkhistoryCumulant.py", line 65, in raiseError
    assert 0,"错误信息：\n"+"\n".join(log)
AssertionError: 错误信息：
项目id为528的计算点如下：
RCS_Plant_Load_Accum累积量数据:{'2017-10-18 22:50:00': 4849693.221298483, '2017-10-18 22:55:00': 4849690.495424174}
qunlou_Plant_Cost_Accum累积量数据:{'2017-10-18 22:50:00': 3179825.647520829, '2017-10-18 22:55:00': 3179825.639947496}
qunlou_Plant_Load_Accum累积量数据:{'2017-10-17 20:25:00': 1526716.1398333332, '2017-10-17 20:30:00': 1526687.8291666666}
talou_CTGroup_Power_Accum累积量数据:{'2017-10-18 09:35:00': 9647.246666666646, '2017-10-18 09:30:00': 9648.446666666647}
talou_ChGroup_Power_Accum累积量数据:{'2017-10-19 20:40:00': 443139.36583333334, '2017-10-19 20:35:00': 443139.44916666666}
talou_Plant_Load_Accum累积量数据:{'2017-10-18 22:50:00': 3305085.3677937966, '2017-10-18 22:55:00': 3305082.5710861534}
项目id为120的计算点如下：
Accum_IceChargPGroupTotal101_GroupCost累积量数据:{'2017-10-17 17:25:00': 301808.9887500005, '2017-10-17 17:20:00': 301808.98875000054}
Accum_Plant_GroupCost累积量数据:{'2017-10-19 00:05:00': 2287650.339709661, '2017-10-19 00:00:00': 2287660.995959661}
Accum_Plant_GroupElecUse累积量数据:{'2017-10-19 00:05:00': 3079846.94, '2017-10-19 00:00:00': 3079878.19}
Accum_PumpGroupTotal001_GroupElecUse累积量数据:{'2017-10-19 00:05:00': 2611750.0, '2017-10-19 00:00:00': 2611781.25}
项目id为539的计算点如下：
xiqu_Plant_Load_Accum累积量数据:{'2017-10-17 11:40:00': 507823.15, '2017-10-17 11:35:00': 507842.15}
项目id为540的计算点如下：
Accum_RealTimePower_svr累积量数据:{'2017-10-17 21:10:00': 1923208.8493064197, '2017-10-17 21:05:00': 1923208.84930642}
qk01_Plant_Cost_Accum累积量数据:{'2017-10-19 10:45:00': 1812268.450745515, '2017-10-19 10:50:00': 1812268.4507455148}
qk01_Plant_Power_Accum累积量数据:{'2017-10-17 21:10:00': 1923208.8493064197, '2017-10-17 21:05:00': 1923208.84930642}
项目id为15的计算点如下：
Accum_B3F_Plant_Load累积量数据:{'2017-10-17 18:45:00': 333046.5846605991, '2017-10-17 18:50:00': 333046.52303754265}
Accum_RF_Plant_Load累积量数据:{'2017-10-18 17:55:00': 284853.55833333335, '2017-10-18 17:50:00': 284855.9166666667}
Accum_i6F_Plant_Load累积量数据:{'2017-10-17 18:45:00': 612014.8583333333, '2017-10-17 18:40:00': 612024.9416666667}

[2017-10-20 11:28:35]---邮箱为空!
[2017-10-20 11:28:47]---错误case个数为1!
[2017-10-20 11:28:47]---Traceback (most recent call last):
  File "D:\Beop-OnlineTest\interfaceTest\calcPoint_Case\Calc044checkhistoryCumulant.py", line 58, in Test
    self.raiseError(message)
  File "D:\Beop-OnlineTest\interfaceTest\calcPoint_Case\Calc044checkhistoryCumulant.py", line 65, in raiseError
    assert 0,"错误信息：\n"+"\n".join(log)
AssertionError: 错误信息：
项目id为528的计算点如下：
RCS_Plant_Load_Accum累积量数据:{'2017-10-18 22:50:00': 4849693.221298483, '2017-10-18 22:55:00': 4849690.495424174}
qunlou_Plant_Cost_Accum累积量数据:{'2017-10-18 22:50:00': 3179825.647520829, '2017-10-18 22:55:00': 3179825.639947496}
qunlou_Plant_Load_Accum累积量数据:{'2017-10-17 20:25:00': 1526716.1398333332, '2017-10-17 20:30:00': 1526687.8291666666}
talou_CTGroup_Power_Accum累积量数据:{'2017-10-18 09:35:00': 9647.246666666646, '2017-10-18 09:30:00': 9648.446666666647}
talou_ChGroup_Power_Accum累积量数据:{'2017-10-19 20:40:00': 443139.36583333334, '2017-10-19 20:35:00': 443139.44916666666}
talou_Plant_Load_Accum累积量数据:{'2017-10-18 22:50:00': 3305085.3677937966, '2017-10-18 22:55:00': 3305082.5710861534}
项目id为120的计算点如下：
Accum_IceChargPGroupTotal101_GroupCost累积量数据:{'2017-10-17 17:25:00': 301808.9887500005, '2017-10-17 17:20:00': 301808.98875000054}
Accum_Plant_GroupCost累积量数据:{'2017-10-19 00:05:00': 2287650.339709661, '2017-10-19 00:00:00': 2287660.995959661}
Accum_Plant_GroupElecUse累积量数据:{'2017-10-19 00:05:00': 3079846.94, '2017-10-19 00:00:00': 3079878.19}
Accum_PumpGroupTotal001_GroupElecUse累积量数据:{'2017-10-19 00:05:00': 2611750.0, '2017-10-19 00:00:00': 2611781.25}
项目id为539的计算点如下：
xiqu_Plant_Load_Accum累积量数据:{'2017-10-17 11:40:00': 507823.15, '2017-10-17 11:35:00': 507842.15}
项目id为540的计算点如下：
Accum_RealTimePower_svr累积量数据:{'2017-10-17 21:10:00': 1923208.8493064197, '2017-10-17 21:05:00': 1923208.84930642}
qk01_Plant_Cost_Accum累积量数据:{'2017-10-19 10:45:00': 1812268.450745515, '2017-10-19 10:50:00': 1812268.4507455148}
qk01_Plant_Power_Accum累积量数据:{'2017-10-17 21:10:00': 1923208.8493064197, '2017-10-17 21:05:00': 1923208.84930642}
项目id为15的计算点如下：
Accum_B3F_Plant_Load累积量数据:{'2017-10-17 18:45:00': 333046.5846605991, '2017-10-17 18:50:00': 333046.52303754265}
Accum_RF_Plant_Load累积量数据:{'2017-10-18 17:55:00': 284853.55833333335, '2017-10-18 17:50:00': 284855.9166666667}
Accum_i6F_Plant_Load累积量数据:{'2017-10-17 18:45:00': 612014.8583333333, '2017-10-17 18:40:00': 612024.9416666667}

[2017-10-20 11:31:09]---错误case个数为1!
[2017-10-20 11:31:09]---Traceback (most recent call last):
  File "D:\Beop-OnlineTest\interfaceTest\calcPoint_Case\Calc044checkhistoryCumulant.py", line 58, in Test
    self.raiseError(message)
  File "D:\Beop-OnlineTest\interfaceTest\calcPoint_Case\Calc044checkhistoryCumulant.py", line 65, in raiseError
    assert 0,"错误信息：\n"+"\n".join(log)
AssertionError: 错误信息：
项目id为528的计算点如下：
RCS_Plant_Load_Accum累积量数据:{'2017-10-18 22:55:00': 4849690.495424174, '2017-10-18 22:50:00': 4849693.221298483}
qunlou_Plant_Cost_Accum累积量数据:{'2017-10-18 22:55:00': 3179825.639947496, '2017-10-18 22:50:00': 3179825.647520829}
qunlou_Plant_Load_Accum累积量数据:{'2017-10-17 20:30:00': 1526687.8291666666, '2017-10-17 20:25:00': 1526716.1398333332}
talou_CTGroup_Power_Accum累积量数据:{'2017-10-18 09:35:00': 9647.246666666646, '2017-10-18 09:30:00': 9648.446666666647}
talou_ChGroup_Power_Accum累积量数据:{'2017-10-19 20:40:00': 443139.36583333334, '2017-10-19 20:35:00': 443139.44916666666}
talou_Plant_Load_Accum累积量数据:{'2017-10-18 22:55:00': 3305082.5710861534, '2017-10-18 22:50:00': 3305085.3677937966}
项目id为120的计算点如下：
Accum_IceChargPGroupTotal101_GroupCost累积量数据:{'2017-10-17 17:20:00': 301808.98875000054, '2017-10-17 17:25:00': 301808.9887500005}
Accum_Plant_GroupCost累积量数据:{'2017-10-19 00:00:00': 2287660.995959661, '2017-10-19 00:05:00': 2287650.339709661}
Accum_Plant_GroupElecUse累积量数据:{'2017-10-19 00:00:00': 3079878.19, '2017-10-19 00:05:00': 3079846.94}
Accum_PumpGroupTotal001_GroupElecUse累积量数据:{'2017-10-19 00:00:00': 2611781.25, '2017-10-19 00:05:00': 2611750.0}
项目id为539的计算点如下：
xiqu_Plant_Load_Accum累积量数据:{'2017-10-17 11:35:00': 507842.15, '2017-10-17 11:40:00': 507823.15}
项目id为540的计算点如下：
Accum_RealTimePower_svr累积量数据:{'2017-10-17 21:05:00': 1923208.84930642, '2017-10-17 21:10:00': 1923208.8493064197}
qk01_Plant_Cost_Accum累积量数据:{'2017-10-19 10:45:00': 1812268.450745515, '2017-10-19 10:50:00': 1812268.4507455148}
qk01_Plant_Power_Accum累积量数据:{'2017-10-17 21:05:00': 1923208.84930642, '2017-10-17 21:10:00': 1923208.8493064197}
项目id为15的计算点如下：
Accum_B3F_Plant_Load累积量数据:{'2017-10-17 18:45:00': 333046.5846605991, '2017-10-17 18:50:00': 333046.52303754265}
Accum_RF_Plant_Load累积量数据:{'2017-10-18 17:50:00': 284855.9166666667, '2017-10-18 17:55:00': 284853.55833333335}
Accum_i6F_Plant_Load累积量数据:{'2017-10-17 18:40:00': 612024.9416666667, '2017-10-17 18:45:00': 612014.8583333333}

[2017-10-20 11:31:14]---邮箱为空!
[2017-10-20 11:31:28]---错误case个数为1!
[2017-10-20 11:31:28]---Traceback (most recent call last):
  File "D:\Beop-OnlineTest\interfaceTest\calcPoint_Case\Calc044checkhistoryCumulant.py", line 58, in Test
    self.raiseError(message)
  File "D:\Beop-OnlineTest\interfaceTest\calcPoint_Case\Calc044checkhistoryCumulant.py", line 65, in raiseError
    assert 0,"错误信息：\n"+"\n".join(log)
AssertionError: 错误信息：
项目id为528的计算点如下：
RCS_Plant_Load_Accum累积量数据:{'2017-10-18 22:55:00': 4849690.495424174, '2017-10-18 22:50:00': 4849693.221298483}
qunlou_Plant_Cost_Accum累积量数据:{'2017-10-18 22:55:00': 3179825.639947496, '2017-10-18 22:50:00': 3179825.647520829}
qunlou_Plant_Load_Accum累积量数据:{'2017-10-17 20:30:00': 1526687.8291666666, '2017-10-17 20:25:00': 1526716.1398333332}
talou_CTGroup_Power_Accum累积量数据:{'2017-10-18 09:35:00': 9647.246666666646, '2017-10-18 09:30:00': 9648.446666666647}
talou_ChGroup_Power_Accum累积量数据:{'2017-10-19 20:40:00': 443139.36583333334, '2017-10-19 20:35:00': 443139.44916666666}
talou_Plant_Load_Accum累积量数据:{'2017-10-18 22:55:00': 3305082.5710861534, '2017-10-18 22:50:00': 3305085.3677937966}
项目id为120的计算点如下：
Accum_IceChargPGroupTotal101_GroupCost累积量数据:{'2017-10-17 17:20:00': 301808.98875000054, '2017-10-17 17:25:00': 301808.9887500005}
Accum_Plant_GroupCost累积量数据:{'2017-10-19 00:00:00': 2287660.995959661, '2017-10-19 00:05:00': 2287650.339709661}
Accum_Plant_GroupElecUse累积量数据:{'2017-10-19 00:00:00': 3079878.19, '2017-10-19 00:05:00': 3079846.94}
Accum_PumpGroupTotal001_GroupElecUse累积量数据:{'2017-10-19 00:00:00': 2611781.25, '2017-10-19 00:05:00': 2611750.0}
项目id为539的计算点如下：
xiqu_Plant_Load_Accum累积量数据:{'2017-10-17 11:35:00': 507842.15, '2017-10-17 11:40:00': 507823.15}
项目id为540的计算点如下：
Accum_RealTimePower_svr累积量数据:{'2017-10-17 21:05:00': 1923208.84930642, '2017-10-17 21:10:00': 1923208.8493064197}
qk01_Plant_Cost_Accum累积量数据:{'2017-10-19 10:45:00': 1812268.450745515, '2017-10-19 10:50:00': 1812268.4507455148}
qk01_Plant_Power_Accum累积量数据:{'2017-10-17 21:05:00': 1923208.84930642, '2017-10-17 21:10:00': 1923208.8493064197}
项目id为15的计算点如下：
Accum_B3F_Plant_Load累积量数据:{'2017-10-17 18:45:00': 333046.5846605991, '2017-10-17 18:50:00': 333046.52303754265}
Accum_RF_Plant_Load累积量数据:{'2017-10-18 17:50:00': 284855.9166666667, '2017-10-18 17:55:00': 284853.55833333335}
Accum_i6F_Plant_Load累积量数据:{'2017-10-17 18:40:00': 612024.9416666667, '2017-10-17 18:45:00': 612014.8583333333}

[2017-10-20 11:31:35]---邮箱为空!
[2017-10-20 11:31:51]---错误case个数为1!
[2017-10-20 11:31:51]---Traceback (most recent call last):
  File "D:\Beop-OnlineTest\interfaceTest\calcPoint_Case\Calc044checkhistoryCumulant.py", line 58, in Test
    self.raiseError(message)
  File "D:\Beop-OnlineTest\interfaceTest\calcPoint_Case\Calc044checkhistoryCumulant.py", line 65, in raiseError
    assert 0,"错误信息：\n"+"\n".join(log)
AssertionError: 错误信息：
项目id为528的计算点如下：
RCS_Plant_Load_Accum累积量数据:{'2017-10-18 22:55:00': 4849690.495424174, '2017-10-18 22:50:00': 4849693.221298483}
qunlou_Plant_Cost_Accum累积量数据:{'2017-10-18 22:55:00': 3179825.639947496, '2017-10-18 22:50:00': 3179825.647520829}
qunlou_Plant_Load_Accum累积量数据:{'2017-10-17 20:30:00': 1526687.8291666666, '2017-10-17 20:25:00': 1526716.1398333332}
talou_CTGroup_Power_Accum累积量数据:{'2017-10-18 09:35:00': 9647.246666666646, '2017-10-18 09:30:00': 9648.446666666647}
talou_ChGroup_Power_Accum累积量数据:{'2017-10-19 20:40:00': 443139.36583333334, '2017-10-19 20:35:00': 443139.44916666666}
talou_Plant_Load_Accum累积量数据:{'2017-10-18 22:55:00': 3305082.5710861534, '2017-10-18 22:50:00': 3305085.3677937966}
项目id为120的计算点如下：
Accum_IceChargPGroupTotal101_GroupCost累积量数据:{'2017-10-17 17:20:00': 301808.98875000054, '2017-10-17 17:25:00': 301808.9887500005}
Accum_Plant_GroupCost累积量数据:{'2017-10-19 00:00:00': 2287660.995959661, '2017-10-19 00:05:00': 2287650.339709661}
Accum_Plant_GroupElecUse累积量数据:{'2017-10-19 00:00:00': 3079878.19, '2017-10-19 00:05:00': 3079846.94}
Accum_PumpGroupTotal001_GroupElecUse累积量数据:{'2017-10-19 00:00:00': 2611781.25, '2017-10-19 00:05:00': 2611750.0}
项目id为539的计算点如下：
xiqu_Plant_Load_Accum累积量数据:{'2017-10-17 11:35:00': 507842.15, '2017-10-17 11:40:00': 507823.15}
项目id为540的计算点如下：
Accum_RealTimePower_svr累积量数据:{'2017-10-17 21:05:00': 1923208.84930642, '2017-10-17 21:10:00': 1923208.8493064197}
qk01_Plant_Cost_Accum累积量数据:{'2017-10-19 10:45:00': 1812268.450745515, '2017-10-19 10:50:00': 1812268.4507455148}
qk01_Plant_Power_Accum累积量数据:{'2017-10-17 21:05:00': 1923208.84930642, '2017-10-17 21:10:00': 1923208.8493064197}
项目id为15的计算点如下：
Accum_B3F_Plant_Load累积量数据:{'2017-10-17 18:45:00': 333046.5846605991, '2017-10-17 18:50:00': 333046.52303754265}
Accum_RF_Plant_Load累积量数据:{'2017-10-18 17:50:00': 284855.9166666667, '2017-10-18 17:55:00': 284853.55833333335}
Accum_i6F_Plant_Load累积量数据:{'2017-10-17 18:40:00': 612024.9416666667, '2017-10-17 18:45:00': 612014.8583333333}

[2017-10-20 15:21:03]---错误case个数为1!
[2017-10-20 15:21:03]---Traceback (most recent call last):
  File "D:\Beop-OnlineTest\interfaceTest\base_case\Base024checkRealTimeforGuangming.py", line 74, in connectMysql
    host=self.sqlIp,port=self.sqlPoint, db=self.sqldata,charset='utf8')
  File "C:\Users\PC\AppData\Local\Programs\Python\Python35\lib\site-packages\pymysql\__init__.py", line 90, in Connect
    return Connection(*args, **kwargs)
pymysql.err.InternalError: (1129, "Host '140.207.49.230' is blocked because of many connection errors; unblock with 'mysqladmin flush-hosts'")

During handling of the above exception, another exception occurred:

Traceback (most recent call last):
  File "D:\Beop-OnlineTest\interfaceTest\base_case\Base024checkRealTimeforGuangming.py", line 43, in Test
    data = self.connectMysql(sql)[0]
  File "D:\Beop-OnlineTest\interfaceTest\base_case\Base024checkRealTimeforGuangming.py", line 81, in connectMysql
    assert 0,"错误信息为：%s"%e.__str__()
AssertionError: 错误信息为：(1129, "Host '140.207.49.230' is blocked because of many connection errors; unblock with 'mysqladmin flush-hosts'")

[2017-10-20 15:21:03]---邮箱为空!
Certificate did not match expected hostname: 121.41.28.69. Certificate: {'subjectAltName': (('DNS', 'expertcontainer.beopsmart.com'),), 'notAfter': 'Mar 16 23:59:59 2018 GMT', 'OCSP': ('http://trustasia2-ocsp.digitalcertvalidation.com',), 'version': 3, 'serialNumber': '2CABC0594B027C55A289EF991AA1F16B', 'issuer': ((('countryName', 'CN'),), (('organizationName', 'TrustAsia Technologies, Inc.'),), (('organizationalUnitName', 'Symantec Trust Network'),), (('organizationalUnitName', 'Domain Validated SSL'),), (('commonName', 'TrustAsia DV SSL CA - G5'),)), 'subject': ((('commonName', 'expertcontainer.beopsmart.com'),),), 'caIssuers': ('http://trustasia2-aia.digitalcertvalidation.com/trustasiag5.crt',), 'notBefore': 'Mar 16 00:00:00 2017 GMT'}
[2017-10-20 15:22:11]---错误case个数为1!
[2017-10-20 15:22:12]---Traceback (most recent call last):
  File "D:\Beop-OnlineTest\interfaceTest\base_case\Base024checkRealTimeforGuangming.py", line 74, in connectMysql
    host=self.sqlIp,port=self.sqlPoint, db=self.sqldata,charset='utf8')
  File "C:\Users\PC\AppData\Local\Programs\Python\Python35\lib\site-packages\pymysql\__init__.py", line 90, in Connect
    return Connection(*args, **kwargs)
pymysql.err.InternalError: (1129, "Host '140.207.49.230' is blocked because of many connection errors; unblock with 'mysqladmin flush-hosts'")

During handling of the above exception, another exception occurred:

Traceback (most recent call last):
  File "D:\Beop-OnlineTest\interfaceTest\base_case\Base024checkRealTimeforGuangming.py", line 43, in Test
    data = self.connectMysql(sql)[0]
  File "D:\Beop-OnlineTest\interfaceTest\base_case\Base024checkRealTimeforGuangming.py", line 81, in connectMysql
    assert 0,"错误信息为：%s"%e.__str__()
AssertionError: 错误信息为：(1129, "Host '140.207.49.230' is blocked because of many connection errors; unblock with 'mysqladmin flush-hosts'")

[2017-10-20 15:23:44]---错误case个数为1!
[2017-10-20 15:23:45]---Traceback (most recent call last):
  File "D:\Beop-OnlineTest\interfaceTest\base_case\Base024checkRealTimeforGuangming.py", line 74, in connectMysql
    host=self.sqlIp,port=self.sqlPoint, db=self.sqldata,charset='utf8')
  File "C:\Users\PC\AppData\Local\Programs\Python\Python35\lib\site-packages\pymysql\__init__.py", line 90, in Connect
    return Connection(*args, **kwargs)
pymysql.err.InternalError: (1129, "Host '140.207.49.230' is blocked because of many connection errors; unblock with 'mysqladmin flush-hosts'")

During handling of the above exception, another exception occurred:

Traceback (most recent call last):
  File "D:\Beop-OnlineTest\interfaceTest\base_case\Base024checkRealTimeforGuangming.py", line 43, in Test
    data = self.connectMysql(sql)[0]
  File "D:\Beop-OnlineTest\interfaceTest\base_case\Base024checkRealTimeforGuangming.py", line 81, in connectMysql
    assert 0,"错误信息为：%s"%e.__str__()
AssertionError: 错误信息为：(1129, "Host '140.207.49.230' is blocked because of many connection errors; unblock with 'mysqladmin flush-hosts'")

[2017-10-20 15:24:30]---错误case个数为1!
[2017-10-20 15:24:30]---Traceback (most recent call last):
  File "D:\Beop-OnlineTest\interfaceTest\base_case\Base002expertContainerRun.py", line 40, in Test
    a.raiseError(error,self.testCaseID)
  File "D:\Beop-OnlineTest\interfaceTest\Methods\BeopTools.py", line 156, in raiseError
    assert 0,"\n".join(error)
AssertionError: 错误信息算法容器121.41.28.69接口异常，请检查！
错误信息算法容器42.159.234.15:4000接口异常，请检查！
错误信息算法容器40.71.228.119:4000接口异常，请检查！
错误信息算法容器121.41.28.69:4000接口异常，请检查！

[2017-10-20 15:24:42]---邮箱为空!
[2017-10-20 15:25:40]---错误case个数为1!
[2017-10-20 15:25:41]---Traceback (most recent call last):
  File "D:\Beop-OnlineTest\interfaceTest\base_case\Base024checkRealTimeforGuangming.py", line 74, in connectMysql
    host=self.sqlIp,port=self.sqlPoint, db=self.sqldata,charset='utf8')
  File "C:\Users\PC\AppData\Local\Programs\Python\Python35\lib\site-packages\pymysql\__init__.py", line 90, in Connect
    return Connection(*args, **kwargs)
pymysql.err.InternalError: (1129, "Host '140.207.49.230' is blocked because of many connection errors; unblock with 'mysqladmin flush-hosts'")

During handling of the above exception, another exception occurred:

Traceback (most recent call last):
  File "D:\Beop-OnlineTest\interfaceTest\base_case\Base024checkRealTimeforGuangming.py", line 43, in Test
    data = self.connectMysql(sql)[0]
  File "D:\Beop-OnlineTest\interfaceTest\base_case\Base024checkRealTimeforGuangming.py", line 81, in connectMysql
    assert 0,"错误信息为：%s"%e.__str__()
AssertionError: 错误信息为：(1129, "Host '140.207.49.230' is blocked because of many connection errors; unblock with 'mysqladmin flush-hosts'")

[2017-10-20 15:35:06]---错误case个数为1!
[2017-10-20 15:35:06]---Traceback (most recent call last):
  File "D:\Beop-OnlineTest\interfaceTest\base_case\Base002expertContainerRun.py", line 40, in Test
    a.raiseError(error,self.testCaseID)
  File "D:\Beop-OnlineTest\interfaceTest\Methods\BeopTools.py", line 156, in raiseError
    assert 0,"\n".join(error)
AssertionError: 错误信息算法容器121.41.28.69接口异常，请检查！
错误信息算法容器42.159.234.15:4000接口异常，请检查！
错误信息算法容器40.71.228.119:4000接口异常，请检查！
错误信息算法容器121.41.28.69:4000接口异常，请检查！

[2017-10-20 15:35:26]---邮箱为空!
[2017-10-20 15:51:37]---错误case个数为1!
[2017-10-20 15:51:37]---Traceback (most recent call last):
  File "D:\Beop-OnlineTest\interfaceTest\base_case\Base002expertContainerRun.py", line 40, in Test
    a.raiseError(error,self.testCaseID)
  File "D:\Beop-OnlineTest\interfaceTest\Methods\BeopTools.py", line 156, in raiseError
    assert 0,"\n".join(error)
AssertionError: 错误信息算法容器121.41.28.69接口异常，请检查！
错误信息算法容器42.159.234.15:4000接口异常，请检查！
错误信息算法容器40.71.228.119:4000接口异常，请检查！
错误信息算法容器121.41.28.69:4000接口异常，请检查！

[2017-10-20 15:51:54]---邮箱为空!
[2017-10-20 15:55:07]---错误case个数为1!
[2017-10-20 15:55:07]---Traceback (most recent call last):
  File "D:\Beop-OnlineTest\interfaceTest\base_case\Base002expertContainerRun.py", line 40, in Test
    a.raiseError(error,self.testCaseID)
  File "D:\Beop-OnlineTest\interfaceTest\Methods\BeopTools.py", line 156, in raiseError
    assert 0,"\n".join(error)
AssertionError: 错误信息算法容器121.41.28.69接口异常，请检查！
错误信息算法容器42.159.234.15:4000接口异常，请检查！
错误信息算法容器40.71.228.119:4000接口异常，请检查！
错误信息算法容器121.41.28.69:4000接口异常，请检查！

发送邮件出错,请检查!{'woody.wu@rnbtech.com.hk': (503, b"RCPT account isn't a local account")}
[2017-10-20 16:12:50]---错误case个数为1!
[2017-10-20 16:12:50]---Traceback (most recent call last):
  File "D:\Beop-OnlineTest\interfaceTest\base_case\Base002expertContainerRun.py", line 40, in Test
    a.raiseError(error,self.testCaseID)
  File "D:\Beop-OnlineTest\interfaceTest\Methods\BeopTools.py", line 156, in raiseError
    assert 0,"\n".join(error)
AssertionError: 错误信息算法容器121.41.28.69接口异常，请检查！
错误信息算法容器42.159.234.15:4000接口异常，请检查！
错误信息算法容器40.71.228.119:4000接口异常，请检查！
错误信息算法容器121.41.28.69:4000接口异常，请检查！

[2017-10-20 16:12:57]---邮箱为空!
[2017-10-26 16:09:13]---错误case个数为1!
[2017-10-26 16:09:13]---Traceback (most recent call last):
  File "D:\Beop-OnlineTest\interfaceTest\base_case\Base002expertContainerRun.py", line 40, in Test
    a.raiseError(error,self.testCaseID)
  File "D:\Beop-OnlineTest\interfaceTest\Methods\BeopTools.py", line 156, in raiseError
    assert 0,"\n".join(error)
AssertionError: 错误信息算法容器121.41.28.69接口异常，请检查！
错误信息算法容器42.159.234.15:4000接口异常，请检查！
错误信息算法容器40.71.228.119:4000接口异常，请检查！
错误信息算法容器121.41.28.69:4000接口异常，请检查！

[2017-10-26 16:09:39]---邮箱为空!
[2017-10-26 16:13:13]---错误case个数为2!
[2017-10-26 16:13:13]---Traceback (most recent call last):
  File "D:\Beop-OnlineTest\interfaceTest\base_case\Base002expertContainerRun.py", line 40, in Test
    a.raiseError(error,self.testCaseID)
  File "D:\Beop-OnlineTest\interfaceTest\Methods\BeopTools.py", line 156, in raiseError
    assert 0,"\n".join(error)
AssertionError: 错误信息算法容器121.41.28.69接口异常，请检查！
错误信息算法容器42.159.234.15:4000接口异常，请检查！
错误信息算法容器40.71.228.119:4000接口异常，请检查！
错误信息算法容器121.41.28.69:4000接口异常，请检查！

[2017-10-26 16:14:30]---邮箱为空!
[2017-10-26 16:14:32]---错误case个数为2!
[2017-10-26 16:14:33]---Traceback (most recent call last):
  File "D:\Beop-OnlineTest\interfaceTest\base_case\Base003login.py", line 34, in login
    loginResult = BeopTools.getInstance().postData(url, userTemplate,t=TIMEOUT)
  File "D:\Beop-OnlineTest\interfaceTest\Methods\BeopTools.py", line 400, in postData
    assert 0,"错误信息本次发送post请求读取%s接口参数:%s返回状态码不为200为%s!" % (url,json.dumps(data),str(r.status_code))
AssertionError: 错误信息本次发送post请求读取http://beop.rnbtech.com.hk/login接口参数:{"name": "projecttest@rnbtech.com.hk", "pwd": "Rnbtech1103", "agent": {}}返回状态码不为200为500!

During handling of the above exception, another exception occurred:

Traceback (most recent call last):
  File "D:\Beop-OnlineTest\interfaceTest\base_case\Base003login.py", line 45, in Test
    loginResult = self.login(user,password)
  File "D:\Beop-OnlineTest\interfaceTest\base_case\Base003login.py", line 36, in login
    assert 0, '错误信息发送%s数据访问%s接口失败! 可能导致用户无法登陆!timeout: %ss' % (json.dumps(userTemplate), url, TIMEOUT)
AssertionError: 错误信息发送{"name": "projecttest@rnbtech.com.hk", "pwd": "Rnbtech1103", "agent": {}}数据访问http://beop.rnbtech.com.hk/login接口失败! 可能导致用户无法登陆!timeout: 60s

[2017-10-26 16:15:22]---邮箱为空!
[2017-10-26 16:19:16]---错误case个数为1!
[2017-10-26 16:19:17]---Traceback (most recent call last):
  File "D:\Beop-OnlineTest\interfaceTest\base_case\Base002expertContainerRun.py", line 40, in Test
    a.raiseError(error,self.testCaseID)
  File "D:\Beop-OnlineTest\interfaceTest\Methods\BeopTools.py", line 156, in raiseError
    assert 0,"\n".join(error)
AssertionError: 错误信息算法容器121.41.28.69接口异常，请检查！
错误信息算法容器42.159.234.15:4000接口异常，请检查！
错误信息算法容器40.71.228.119:4000接口异常，请检查！
错误信息算法容器121.41.28.69:4000接口异常，请检查！

[2017-12-14 10:48:00]---错误case个数为1!
[2017-12-14 10:48:00]---Traceback (most recent call last):
  File "D:\Beop-OnlineTest\interfaceTest\base_case\Base002expertContainerRun.py", line 41, in Test
    a.raiseError(error,self.testCaseID)
  File "D:\Beop-OnlineTest\interfaceTest\Methods\BeopTools.py", line 155, in raiseError
    assert 0,"\n".join(error)
AssertionError: 错误信息算法容器121.41.28.69接口异常，请检查！
错误信息算法容器121.41.28.69异常关闭，请检查！
错误信息算法容器40.71.228.119:4000接口异常，请检查！
错误信息算法容器121.41.28.69:4000异常关闭，请检查！

[2017-12-14 15:58:26]---错误case个数为1!
[2017-12-14 15:58:26]---Traceback (most recent call last):
  File "D:\Beop-OnlineTest\interfaceTest\base_case\Base024checkRealTimeforGuangming.py", line 65, in Test
    a.raiseError(self.error,self.testCaseID)
  File "D:\Beop-OnlineTest\interfaceTest\Methods\BeopTools.py", line 155, in raiseError
    assert 0,"\n".join(error)
AssertionError: 光明项目数据库表t_data_realtime_fridge中实时数据10分钟内没有更新，见下表：
20030000000001 C82V160901H4097 2017-11-06 20:21:20 2017-11-28 03:00:30

20030000000002 C82V160901H4095 2017-12-14 15:08:45 2017-12-14 15:30:01

20030000000003 HDGM2017003 2017-12-14 15:18:33 2017-12-14 15:30:01

20030000000004 C82V160901H4143 2017-12-14 15:03:30 2017-12-14 15:30:01

20030000000005 C82V160901H4142 2017-12-14 15:07:51 2017-12-14 15:30:01

20030000000006 C82V160901H4141 2017-12-14 15:12:07 2017-12-14 15:30:01

20030000000007 C82V160901H4140 2017-12-14 15:06:07 2017-12-14 15:30:01

20030000000008 C82V160901H4139 2017-12-14 07:41:38 2017-12-14 15:30:01

20030000000009 C82V160901H4138 2017-12-14 15:14:34 2017-12-14 15:30:01

20030000000010 C82V160901H4137 2017-12-14 15:11:38 2017-12-14 15:30:01

20030000000011 C82V160901H4136 2017-12-11 16:30:15 2017-12-14 15:30:01

20030000000012 C82V160901H4135 2017-12-14 15:20:12 2017-12-14 15:30:01

20030000000013 C82V160901H4134 2017-12-14 14:06:59 2017-12-14 15:30:01

20030000000014 C82V160901H4133 2017-12-14 15:18:50 2017-12-14 15:30:01

20030000000015 C82V160901H4132 2017-12-14 15:22:19 2017-12-14 15:30:01

20030000000016 C82V160901H4131 2017-12-14 15:28:40 2017-12-14 15:30:01

20030000000017 C82V160901H4148 2017-12-12 22:16:10 2017-12-14 15:30:01

20030000000018 C82V160901H4094 2017-12-14 15:06:37 2017-12-14 15:30:01

20030000000019 C82V160901H4092 2017-12-14 15:24:37 2017-12-14 15:30:01

20030000000020 C82V160901H4091 2017-12-14 15:27:33 2017-12-14 15:30:01

20030000000021 C82V160901H4090 2017-12-14 15:01:26 2017-12-14 15:30:01

20030000000022 C82V160901H4064 2017-12-14 13:35:07 2017-12-14 15:30:01

20030000000023 C82V160901H4061 2017-12-14 15:09:48 2017-12-14 15:30:01

20030000000024 C82V160901H4058 2017-12-14 15:00:24 2017-12-14 15:30:01

20030000000025 C82V160901H4057 2017-12-14 15:09:33 2017-12-14 15:30:01

20030000000026 C82V160901H4054 2017-12-14 15:09:32 2017-12-14 15:30:01

20030000000027 C82V160901H4052 2017-12-14 15:28:54 2017-12-14 15:30:01

20030000000028 C82V160901H4051 2017-12-14 15:26:36 2017-12-14 15:30:01

20030000000030 C82V160901H4047 2017-12-14 15:28:23 2017-12-14 15:30:01

20030000000031 C82V160901H4045 2017-12-14 15:27:34 2017-12-14 15:30:01

20030000000032 C82V160901H4042 2017-12-14 15:09:29 2017-12-14 15:30:01

20030000000033 C82V160901H4040 2017-12-14 15:07:49 2017-12-14 15:30:01

20030000000034 C82V160901H4039 2017-12-14 15:00:19 2017-12-14 15:30:01

20030000000035 C82V160901H4033 2017-12-14 15:18:52 2017-12-14 15:30:01

20030000000037 C82V160901H3680 2017-12-02 13:38:22 2017-12-14 15:30:01

20030000000038 C82V160901H3677 2017-12-14 15:29:10 2017-12-14 15:30:01

20030000000040 C82V160901H3674 2017-12-02 11:24:55 2017-12-14 15:30:01

20030000000041 C82V160901H3673 2017-12-14 15:26:19 2017-12-14 15:30:01

20030000000042 C82V160901H3672 2017-12-14 15:09:17 2017-12-14 15:30:01

20030000000043 C82V160901H3671 2017-12-14 15:04:31 2017-12-14 15:30:01

20030000000044 C82V160901H3670 2017-12-14 11:38:00 2017-12-14 15:30:01

20030000000045 C82V160901H3669 2017-11-05 14:47:07 2017-11-28 03:00:30

20030000000046 C82V160901H3668 2017-12-14 15:12:06 2017-12-14 15:30:01

20030000000048 C82V160901H3665 2017-12-14 15:16:24 2017-12-14 15:30:01

20030000000049 C82V160901H3664 2017-11-28 21:53:54 2017-12-14 15:30:01

20030000000050 C82V160901H3663 2017-12-08 13:05:11 2017-12-14 15:30:01

20030000000051 C82V160901H3662 2017-11-05 07:23:27 2017-11-28 03:00:30

20030000000052 C82V160901H3658 2017-11-01 13:31:18 2017-11-28 03:00:30

20030000000053 C82V160901H3656 2017-12-14 15:10:07 2017-12-14 15:30:01

20030000000055 C82V160901H3266 2017-12-14 15:20:27 2017-12-14 15:30:01

20030000000056 C82V160901H3263 2017-12-14 15:16:07 2017-12-14 15:30:01

20030000000057 C82V160901H3262 2017-12-14 15:17:47 2017-12-14 15:30:01

20030000000060 C82V160901H3259 2017-12-14 15:28:33 2017-12-14 15:30:01

20030000000061 C82V160901H4167 2017-12-14 15:15:28 2017-12-14 15:30:01

20030000000062 C82V160901H4166 2017-12-14 15:00:10 2017-12-14 15:30:01

20030000000063 C82V160901H4165 2017-12-14 15:26:23 2017-12-14 15:30:01

20030000000064 C82V160901H4164 2017-12-12 08:07:19 2017-12-14 15:30:01

20030000000065 C82V160901H4163 2017-12-14 15:15:08 2017-12-14 15:30:01

20030000000066 C82V160901H4162 2017-12-14 15:29:38 2017-12-14 15:30:01

20030000000067 C82V160901H4160 2017-12-14 15:18:30 2017-12-14 15:30:01

20030000000068 C82V160901H4159 2017-12-01 19:18:07 2017-12-14 15:30:01

20030000000069 C82V160901H4158 2017-12-14 15:27:02 2017-12-14 15:30:01

20030000000070 C82V160901H4157 2017-12-14 15:01:18 2017-12-14 15:30:01

20030000000071 C82V160901H4156 2017-12-13 22:32:00 2017-12-14 15:30:01

20030000000072 C82V160901H4155 2017-11-03 04:25:16 2017-11-28 03:00:30

20030000000073 C82V160901H4154 2017-11-23 16:27:06 2017-11-28 03:00:30

20030000000074 C82V160901H4153 2017-12-14 15:11:12 2017-12-14 15:30:01

20030000000075 C82V160901H4036 2017-12-14 15:28:32 2017-12-14 15:30:01

20030000000076 C82V160901H4035 2017-12-14 15:26:47 2017-12-14 15:30:01

20030000000077 C82V160901H3268 2017-12-14 15:27:52 2017-12-14 15:30:01

20030000000078 C82V160901H3265 2017-12-14 15:19:33 2017-12-14 15:30:01

20030000000079 C82V160901H4102 2017-12-14 15:29:18 2017-12-14 15:30:01

20030000000080 C82V160901H4100 2017-12-14 15:02:21 2017-12-14 15:30:01

20030000000084 C82V160901H3683 2017-12-14 15:23:22 2017-12-14 15:30:01

20030000000085 C82V160901H3681 2017-12-14 15:25:21 2017-12-14 15:30:01

20030000000086 C82V160901H3678 2017-12-14 15:28:15 2017-12-14 15:30:01

20030000000087 C82V160901H3666 2017-12-14 15:15:04 2017-12-14 15:30:01

20030000000088 C82V160901H3661 2017-12-14 15:06:55 2017-12-14 15:30:01

20030000000090 C82V160901H3659 2017-12-14 15:21:32 2017-12-14 15:30:01

20030000000091 C82V160901H3654 2017-10-31 20:13:09 2017-11-28 03:00:30


[2017-12-14 15:58:26]---邮箱为空!
[2017-12-14 15:59:34]---错误case个数为1!
[2017-12-14 15:59:34]---Traceback (most recent call last):
  File "D:\Beop-OnlineTest\interfaceTest\base_case\Base024checkRealTimeforGuangming.py", line 65, in Test
    a.raiseError(self.error,self.testCaseID)
  File "D:\Beop-OnlineTest\interfaceTest\Methods\BeopTools.py", line 155, in raiseError
    assert 0,"\n".join(error)
AssertionError: 光明项目数据库表t_data_realtime_fridge中实时数据10分钟内没有更新，见下表：
20030000000001 C82V160901H4097 2017-11-06 20:21:20 2017-11-28 03:00:30

20030000000002 C82V160901H4095 2017-12-14 15:08:45 2017-12-14 15:30:01

20030000000003 HDGM2017003 2017-12-14 15:18:33 2017-12-14 15:30:01

20030000000004 C82V160901H4143 2017-12-14 15:03:30 2017-12-14 15:30:01

20030000000005 C82V160901H4142 2017-12-14 15:07:51 2017-12-14 15:30:01

20030000000006 C82V160901H4141 2017-12-14 15:12:07 2017-12-14 15:30:01

20030000000007 C82V160901H4140 2017-12-14 15:06:07 2017-12-14 15:30:01

20030000000008 C82V160901H4139 2017-12-14 07:41:38 2017-12-14 15:30:01

20030000000009 C82V160901H4138 2017-12-14 15:14:34 2017-12-14 15:30:01

20030000000010 C82V160901H4137 2017-12-14 15:11:38 2017-12-14 15:30:01

20030000000011 C82V160901H4136 2017-12-11 16:30:15 2017-12-14 15:30:01

20030000000012 C82V160901H4135 2017-12-14 15:20:12 2017-12-14 15:30:01

20030000000013 C82V160901H4134 2017-12-14 14:06:59 2017-12-14 15:30:01

20030000000014 C82V160901H4133 2017-12-14 15:18:50 2017-12-14 15:30:01

20030000000015 C82V160901H4132 2017-12-14 15:22:19 2017-12-14 15:30:01

20030000000016 C82V160901H4131 2017-12-14 15:28:40 2017-12-14 15:30:01

20030000000017 C82V160901H4148 2017-12-12 22:16:10 2017-12-14 15:30:01

20030000000018 C82V160901H4094 2017-12-14 15:06:37 2017-12-14 15:30:01

20030000000019 C82V160901H4092 2017-12-14 15:24:37 2017-12-14 15:30:01

20030000000020 C82V160901H4091 2017-12-14 15:27:33 2017-12-14 15:30:01

20030000000021 C82V160901H4090 2017-12-14 15:01:26 2017-12-14 15:30:01

20030000000022 C82V160901H4064 2017-12-14 13:35:07 2017-12-14 15:30:01

20030000000023 C82V160901H4061 2017-12-14 15:09:48 2017-12-14 15:30:01

20030000000024 C82V160901H4058 2017-12-14 15:00:24 2017-12-14 15:30:01

20030000000025 C82V160901H4057 2017-12-14 15:09:33 2017-12-14 15:30:01

20030000000026 C82V160901H4054 2017-12-14 15:09:32 2017-12-14 15:30:01

20030000000027 C82V160901H4052 2017-12-14 15:28:54 2017-12-14 15:30:01

20030000000028 C82V160901H4051 2017-12-14 15:26:36 2017-12-14 15:30:01

20030000000030 C82V160901H4047 2017-12-14 15:28:23 2017-12-14 15:30:01

20030000000031 C82V160901H4045 2017-12-14 15:27:34 2017-12-14 15:30:01

20030000000032 C82V160901H4042 2017-12-14 15:09:29 2017-12-14 15:30:01

20030000000033 C82V160901H4040 2017-12-14 15:07:49 2017-12-14 15:30:01

20030000000034 C82V160901H4039 2017-12-14 15:00:19 2017-12-14 15:30:01

20030000000035 C82V160901H4033 2017-12-14 15:18:52 2017-12-14 15:30:01

20030000000037 C82V160901H3680 2017-12-02 13:38:22 2017-12-14 15:30:01

20030000000038 C82V160901H3677 2017-12-14 15:29:10 2017-12-14 15:30:01

20030000000040 C82V160901H3674 2017-12-02 11:24:55 2017-12-14 15:30:01

20030000000041 C82V160901H3673 2017-12-14 15:26:19 2017-12-14 15:30:01

20030000000042 C82V160901H3672 2017-12-14 15:09:17 2017-12-14 15:30:01

20030000000043 C82V160901H3671 2017-12-14 15:04:31 2017-12-14 15:30:01

20030000000044 C82V160901H3670 2017-12-14 11:38:00 2017-12-14 15:30:01

20030000000045 C82V160901H3669 2017-11-05 14:47:07 2017-11-28 03:00:30

20030000000046 C82V160901H3668 2017-12-14 15:12:06 2017-12-14 15:30:01

20030000000048 C82V160901H3665 2017-12-14 15:16:24 2017-12-14 15:30:01

20030000000049 C82V160901H3664 2017-11-28 21:53:54 2017-12-14 15:30:01

20030000000050 C82V160901H3663 2017-12-08 13:05:11 2017-12-14 15:30:01

20030000000051 C82V160901H3662 2017-11-05 07:23:27 2017-11-28 03:00:30

20030000000052 C82V160901H3658 2017-11-01 13:31:18 2017-11-28 03:00:30

20030000000053 C82V160901H3656 2017-12-14 15:10:07 2017-12-14 15:30:01

20030000000055 C82V160901H3266 2017-12-14 15:20:27 2017-12-14 15:30:01

20030000000056 C82V160901H3263 2017-12-14 15:16:07 2017-12-14 15:30:01

20030000000057 C82V160901H3262 2017-12-14 15:17:47 2017-12-14 15:30:01

20030000000060 C82V160901H3259 2017-12-14 15:28:33 2017-12-14 15:30:01

20030000000061 C82V160901H4167 2017-12-14 15:15:28 2017-12-14 15:30:01

20030000000062 C82V160901H4166 2017-12-14 15:00:10 2017-12-14 15:30:01

20030000000063 C82V160901H4165 2017-12-14 15:26:23 2017-12-14 15:30:01

20030000000064 C82V160901H4164 2017-12-12 08:07:19 2017-12-14 15:30:01

20030000000065 C82V160901H4163 2017-12-14 15:15:08 2017-12-14 15:30:01

20030000000066 C82V160901H4162 2017-12-14 15:29:38 2017-12-14 15:30:01

20030000000067 C82V160901H4160 2017-12-14 15:18:30 2017-12-14 15:30:01

20030000000068 C82V160901H4159 2017-12-01 19:18:07 2017-12-14 15:30:01

20030000000069 C82V160901H4158 2017-12-14 15:27:02 2017-12-14 15:30:01

20030000000070 C82V160901H4157 2017-12-14 15:01:18 2017-12-14 15:30:01

20030000000071 C82V160901H4156 2017-12-13 22:32:00 2017-12-14 15:30:01

20030000000072 C82V160901H4155 2017-11-03 04:25:16 2017-11-28 03:00:30

20030000000073 C82V160901H4154 2017-11-23 16:27:06 2017-11-28 03:00:30

20030000000074 C82V160901H4153 2017-12-14 15:11:12 2017-12-14 15:30:01

20030000000075 C82V160901H4036 2017-12-14 15:28:32 2017-12-14 15:30:01

20030000000076 C82V160901H4035 2017-12-14 15:26:47 2017-12-14 15:30:01

20030000000077 C82V160901H3268 2017-12-14 15:27:52 2017-12-14 15:30:01

20030000000078 C82V160901H3265 2017-12-14 15:19:33 2017-12-14 15:30:01

20030000000079 C82V160901H4102 2017-12-14 15:29:18 2017-12-14 15:30:01

20030000000080 C82V160901H4100 2017-12-14 15:02:21 2017-12-14 15:30:01

20030000000084 C82V160901H3683 2017-12-14 15:23:22 2017-12-14 15:30:01

20030000000085 C82V160901H3681 2017-12-14 15:25:21 2017-12-14 15:30:01

20030000000086 C82V160901H3678 2017-12-14 15:28:15 2017-12-14 15:30:01

20030000000087 C82V160901H3666 2017-12-14 15:15:04 2017-12-14 15:30:01

20030000000088 C82V160901H3661 2017-12-14 15:06:55 2017-12-14 15:30:01

20030000000090 C82V160901H3659 2017-12-14 15:21:32 2017-12-14 15:30:01

20030000000091 C82V160901H3654 2017-10-31 20:13:09 2017-11-28 03:00:30


[2017-12-14 16:05:43]---错误case个数为1!
[2017-12-14 16:05:43]---Traceback (most recent call last):
  File "D:\Beop-OnlineTest\interfaceTest\base_case\Base024checkRealTimeforGuangming.py", line 65, in Test
    a.raiseError(self.error,self.testCaseID)
  File "D:\Beop-OnlineTest\interfaceTest\Methods\BeopTools.py", line 155, in raiseError
    assert 0,"\n".join(error)
AssertionError: 光明项目数据库表t_data_realtime_fridge中实时数据10分钟内没有更新，见下表：
20030000000001 C82V160901H4097 2017-11-06 20:21:20 2017-11-28 03:00:30

20030000000045 C82V160901H3669 2017-11-05 14:47:07 2017-11-28 03:00:30

20030000000051 C82V160901H3662 2017-11-05 07:23:27 2017-11-28 03:00:30

20030000000052 C82V160901H3658 2017-11-01 13:31:18 2017-11-28 03:00:30

20030000000072 C82V160901H4155 2017-11-03 04:25:16 2017-11-28 03:00:30

20030000000073 C82V160901H4154 2017-11-23 16:27:06 2017-11-28 03:00:30

20030000000091 C82V160901H3654 2017-10-31 20:13:09 2017-11-28 03:00:30


[2017-12-14 16:05:43]---邮箱为空!
[2017-12-14 16:07:17]---错误case个数为1!
[2017-12-14 16:07:18]---Traceback (most recent call last):
  File "D:\Beop-OnlineTest\interfaceTest\base_case\Base024checkRealTimeforGuangming.py", line 65, in Test
    a.raiseError(self.error,self.testCaseID)
  File "D:\Beop-OnlineTest\interfaceTest\Methods\BeopTools.py", line 155, in raiseError
    assert 0,"\n".join(error)
AssertionError: 光明项目数据库表t_data_realtime_fridge中实时数据10分钟内没有更新，见下表：
20030000000001 C82V160901H4097 2017-11-06 20:21:20 2017-11-28 03:00:30

20030000000045 C82V160901H3669 2017-11-05 14:47:07 2017-11-28 03:00:30

20030000000051 C82V160901H3662 2017-11-05 07:23:27 2017-11-28 03:00:30

20030000000052 C82V160901H3658 2017-11-01 13:31:18 2017-11-28 03:00:30

20030000000072 C82V160901H4155 2017-11-03 04:25:16 2017-11-28 03:00:30

20030000000073 C82V160901H4154 2017-11-23 16:27:06 2017-11-28 03:00:30

20030000000091 C82V160901H3654 2017-10-31 20:13:09 2017-11-28 03:00:30


[2017-12-14 16:15:02]---错误case个数为1!
[2017-12-14 16:15:02]---Traceback (most recent call last):
  File "D:\Beop-OnlineTest\interfaceTest\base_case\Base024checkRealTimeforGuangming.py", line 65, in Test
    a.raiseError(self.error,self.testCaseID)
  File "D:\Beop-OnlineTest\interfaceTest\Methods\BeopTools.py", line 155, in raiseError
    assert 0,"\n".join(error)
AssertionError: 光明项目数据库表t_data_realtime_fridge中实时数据10分钟内没有更新，见下表：<br/>20030000000001&nbspC82V160901H4097&nbsp2017-11-06 20:21:20&nbsp2017-11-28 03:00:30<br/><br/>20030000000002&nbspC82V160901H4095&nbsp2017-12-14 15:38:44&nbsp2017-12-14 16:00:01<br/><br/>20030000000003&nbspHDGM2017003&nbsp2017-12-14 15:59:06&nbsp2017-12-14 16:00:01<br/><br/>20030000000004&nbspC82V160901H4143&nbsp2017-12-14 15:33:30&nbsp2017-12-14 16:00:01<br/><br/>20030000000005&nbspC82V160901H4142&nbsp2017-12-14 15:37:44&nbsp2017-12-14 16:00:01<br/><br/>20030000000006&nbspC82V160901H4141&nbsp2017-12-14 15:42:06&nbsp2017-12-14 16:00:01<br/><br/>20030000000007&nbspC82V160901H4140&nbsp2017-12-14 15:36:06&nbsp2017-12-14 16:00:01<br/><br/>20030000000008&nbspC82V160901H4139&nbsp2017-12-14 07:41:38&nbsp2017-12-14 16:00:01<br/><br/>20030000000009&nbspC82V160901H4138&nbsp2017-12-14 15:44:34&nbsp2017-12-14 16:00:01<br/><br/>20030000000010&nbspC82V160901H4137&nbsp2017-12-14 15:41:38&nbsp2017-12-14 16:00:01<br/><br/>20030000000011&nbspC82V160901H4136&nbsp2017-12-11 16:30:15&nbsp2017-12-14 16:00:01<br/><br/>20030000000012&nbspC82V160901H4135&nbsp2017-12-14 15:50:13&nbsp2017-12-14 16:00:01<br/><br/>20030000000013&nbspC82V160901H4134&nbsp2017-12-14 14:06:59&nbsp2017-12-14 16:00:01<br/><br/>20030000000014&nbspC82V160901H4133&nbsp2017-12-14 15:48:50&nbsp2017-12-14 16:00:01<br/><br/>20030000000015&nbspC82V160901H4132&nbsp2017-12-14 15:52:19&nbsp2017-12-14 16:00:01<br/><br/>20030000000016&nbspC82V160901H4131&nbsp2017-12-14 15:58:41&nbsp2017-12-14 16:00:01<br/><br/>20030000000017&nbspC82V160901H4148&nbsp2017-12-12 22:16:10&nbsp2017-12-14 16:00:01<br/><br/>20030000000018&nbspC82V160901H4094&nbsp2017-12-14 15:36:37&nbsp2017-12-14 16:00:01<br/><br/>20030000000019&nbspC82V160901H4092&nbsp2017-12-14 15:54:38&nbsp2017-12-14 16:00:01<br/><br/>20030000000020&nbspC82V160901H4091&nbsp2017-12-14 15:57:34&nbsp2017-12-14 16:00:01<br/><br/>20030000000021&nbspC82V160901H4090&nbsp2017-12-14 15:31:26&nbsp2017-12-14 16:00:01<br/><br/>20030000000022&nbspC82V160901H4064&nbsp2017-12-14 15:36:08&nbsp2017-12-14 16:00:01<br/><br/>20030000000023&nbspC82V160901H4061&nbsp2017-12-14 15:39:48&nbsp2017-12-14 16:00:01<br/><br/>20030000000024&nbspC82V160901H4058&nbsp2017-12-14 15:30:24&nbsp2017-12-14 16:00:01<br/><br/>20030000000025&nbspC82V160901H4057&nbsp2017-12-14 15:39:29&nbsp2017-12-14 16:00:01<br/><br/>20030000000026&nbspC82V160901H4054&nbsp2017-12-14 15:39:30&nbsp2017-12-14 16:00:01<br/><br/>20030000000027&nbspC82V160901H4052&nbsp2017-12-14 15:58:54&nbsp2017-12-14 16:00:01<br/><br/>20030000000028&nbspC82V160901H4051&nbsp2017-12-14 15:56:36&nbsp2017-12-14 16:00:01<br/><br/>20030000000030&nbspC82V160901H4047&nbsp2017-12-14 15:58:31&nbsp2017-12-14 16:00:01<br/><br/>20030000000031&nbspC82V160901H4045&nbsp2017-12-14 15:57:34&nbsp2017-12-14 16:00:01<br/><br/>20030000000032&nbspC82V160901H4042&nbsp2017-12-14 15:38:20&nbsp2017-12-14 16:00:01<br/><br/>20030000000033&nbspC82V160901H4040&nbsp2017-12-14 15:37:49&nbsp2017-12-14 16:00:01<br/><br/>20030000000034&nbspC82V160901H4039&nbsp2017-12-14 15:30:19&nbsp2017-12-14 16:00:01<br/><br/>20030000000035&nbspC82V160901H4033&nbsp2017-12-14 15:48:53&nbsp2017-12-14 16:00:01<br/><br/>20030000000037&nbspC82V160901H3680&nbsp2017-12-02 13:38:22&nbsp2017-12-14 16:00:01<br/><br/>20030000000038&nbspC82V160901H3677&nbsp2017-12-14 15:54:45&nbsp2017-12-14 16:00:01<br/><br/>20030000000040&nbspC82V160901H3674&nbsp2017-12-02 11:24:55&nbsp2017-12-14 16:00:01<br/><br/>20030000000041&nbspC82V160901H3673&nbsp2017-12-14 15:52:20&nbsp2017-12-14 16:00:01<br/><br/>20030000000042&nbspC82V160901H3672&nbsp2017-12-14 15:34:51&nbsp2017-12-14 16:00:01<br/><br/>20030000000043&nbspC82V160901H3671&nbsp2017-12-14 15:55:36&nbsp2017-12-14 16:00:01<br/><br/>20030000000044&nbspC82V160901H3670&nbsp2017-12-14 11:38:00&nbsp2017-12-14 16:00:01<br/><br/>20030000000045&nbspC82V160901H3669&nbsp2017-11-05 14:47:07&nbsp2017-11-28 03:00:30<br/><br/>20030000000046&nbspC82V160901H3668&nbsp2017-12-14 15:12:06&nbsp2017-12-14 16:00:01<br/><br/>20030000000048&nbspC82V160901H3665&nbsp2017-12-14 15:41:57&nbsp2017-12-14 16:00:01<br/><br/>20030000000049&nbspC82V160901H3664&nbsp2017-11-28 21:53:54&nbsp2017-12-14 16:00:01<br/><br/>20030000000050&nbspC82V160901H3663&nbsp2017-12-08 13:05:11&nbsp2017-12-14 16:00:01<br/><br/>20030000000051&nbspC82V160901H3662&nbsp2017-11-05 07:23:27&nbsp2017-11-28 03:00:30<br/><br/>20030000000052&nbspC82V160901H3658&nbsp2017-11-01 13:31:18&nbsp2017-11-28 03:00:30<br/><br/>20030000000053&nbspC82V160901H3656&nbsp2017-12-14 15:35:41&nbsp2017-12-14 16:00:01<br/><br/>20030000000055&nbspC82V160901H3266&nbsp2017-12-14 15:48:05&nbsp2017-12-14 16:00:01<br/><br/>20030000000056&nbspC82V160901H3263&nbsp2017-12-14 15:58:01&nbsp2017-12-14 16:00:01<br/><br/>20030000000057&nbspC82V160901H3262&nbsp2017-12-14 15:58:20&nbsp2017-12-14 16:00:01<br/><br/>20030000000060&nbspC82V160901H3259&nbsp2017-12-14 15:59:09&nbsp2017-12-14 16:00:01<br/><br/>20030000000061&nbspC82V160901H4167&nbsp2017-12-14 15:45:29&nbsp2017-12-14 16:00:01<br/><br/>20030000000062&nbspC82V160901H4166&nbsp2017-12-14 15:30:10&nbsp2017-12-14 16:00:01<br/><br/>20030000000063&nbspC82V160901H4165&nbsp2017-12-14 15:56:23&nbsp2017-12-14 16:00:01<br/><br/>20030000000064&nbspC82V160901H4164&nbsp2017-12-12 08:07:19&nbsp2017-12-14 16:00:01<br/><br/>20030000000065&nbspC82V160901H4163&nbsp2017-12-14 15:45:09&nbsp2017-12-14 16:00:01<br/><br/>20030000000066&nbspC82V160901H4162&nbsp2017-12-14 15:59:38&nbsp2017-12-14 16:00:01<br/><br/>20030000000067&nbspC82V160901H4160&nbsp2017-12-14 15:48:30&nbsp2017-12-14 16:00:01<br/><br/>20030000000068&nbspC82V160901H4159&nbsp2017-12-01 19:18:07&nbsp2017-12-14 16:00:01<br/><br/>20030000000069&nbspC82V160901H4158&nbsp2017-12-14 15:56:56&nbsp2017-12-14 16:00:01<br/><br/>20030000000070&nbspC82V160901H4157&nbsp2017-12-14 15:31:19&nbsp2017-12-14 16:00:01<br/><br/>20030000000071&nbspC82V160901H4156&nbsp2017-12-13 22:32:00&nbsp2017-12-14 16:00:01<br/><br/>20030000000072&nbspC82V160901H4155&nbsp2017-11-03 04:25:16&nbsp2017-11-28 03:00:30<br/><br/>20030000000073&nbspC82V160901H4154&nbsp2017-11-23 16:27:06&nbsp2017-11-28 03:00:30<br/><br/>20030000000074&nbspC82V160901H4153&nbsp2017-12-14 15:41:08&nbsp2017-12-14 16:00:01<br/><br/>20030000000075&nbspC82V160901H4036&nbsp2017-12-14 15:58:32&nbsp2017-12-14 16:00:01<br/><br/>20030000000076&nbspC82V160901H4035&nbsp2017-12-14 15:56:47&nbsp2017-12-14 16:00:01<br/><br/>20030000000077&nbspC82V160901H3268&nbsp2017-12-14 15:55:20&nbsp2017-12-14 16:00:01<br/><br/>20030000000078&nbspC82V160901H3265&nbsp2017-12-14 15:46:35&nbsp2017-12-14 16:00:01<br/><br/>20030000000079&nbspC82V160901H4102&nbsp2017-12-14 15:59:18&nbsp2017-12-14 16:00:01<br/><br/>20030000000080&nbspC82V160901H4100&nbsp2017-12-14 15:32:21&nbsp2017-12-14 16:00:01<br/><br/>20030000000084&nbspC82V160901H3683&nbsp2017-12-14 15:49:23&nbsp2017-12-14 16:00:01<br/><br/>20030000000085&nbspC82V160901H3681&nbsp2017-12-14 15:51:21&nbsp2017-12-14 16:00:01<br/><br/>20030000000086&nbspC82V160901H3678&nbsp2017-12-14 15:53:50&nbsp2017-12-14 16:00:01<br/><br/>20030000000087&nbspC82V160901H3666&nbsp2017-12-14 15:40:38&nbsp2017-12-14 16:00:01<br/><br/>20030000000088&nbspC82V160901H3661&nbsp2017-12-14 15:58:55&nbsp2017-12-14 16:00:01<br/><br/>20030000000090&nbspC82V160901H3659&nbsp2017-12-14 15:47:59&nbsp2017-12-14 16:00:01<br/><br/>20030000000091&nbspC82V160901H3654&nbsp2017-10-31 20:13:09&nbsp2017-11-28 03:00:30<br/>

[2017-12-14 16:25:14]---错误case个数为1!
[2017-12-14 16:25:14]---Traceback (most recent call last):
  File "D:\Beop-OnlineTest\interfaceTest\base_case\Base024checkRealTimeforGuangming.py", line 65, in Test
    a.raiseError(self.error,self.testCaseID)
  File "D:\Beop-OnlineTest\interfaceTest\Methods\BeopTools.py", line 155, in raiseError
    assert 0,"\n".join(error)
AssertionError: 光明项目数据库表t_data_realtime_fridge中实时数据10分钟内没有更新，见下表：20030000000001 C82V160901H4097 2017-11-06 20:21:20 2017-11-28 03:00:30
20030000000002 C82V160901H4095 2017-12-14 15:38:44 2017-12-14 16:00:01
20030000000003 HDGM2017003 2017-12-14 15:59:06 2017-12-14 16:00:01
20030000000004 C82V160901H4143 2017-12-14 15:33:30 2017-12-14 16:00:01
20030000000005 C82V160901H4142 2017-12-14 15:37:44 2017-12-14 16:00:01
20030000000006 C82V160901H4141 2017-12-14 15:42:06 2017-12-14 16:00:01
20030000000007 C82V160901H4140 2017-12-14 15:36:06 2017-12-14 16:00:01
20030000000008 C82V160901H4139 2017-12-14 07:41:38 2017-12-14 16:00:01
20030000000009 C82V160901H4138 2017-12-14 15:44:34 2017-12-14 16:00:01
20030000000010 C82V160901H4137 2017-12-14 15:41:38 2017-12-14 16:00:01
20030000000011 C82V160901H4136 2017-12-11 16:30:15 2017-12-14 16:00:01
20030000000012 C82V160901H4135 2017-12-14 15:50:13 2017-12-14 16:00:01
20030000000013 C82V160901H4134 2017-12-14 14:06:59 2017-12-14 16:00:01
20030000000014 C82V160901H4133 2017-12-14 15:48:50 2017-12-14 16:00:01
20030000000015 C82V160901H4132 2017-12-14 15:52:19 2017-12-14 16:00:01
20030000000016 C82V160901H4131 2017-12-14 15:58:41 2017-12-14 16:00:01
20030000000017 C82V160901H4148 2017-12-12 22:16:10 2017-12-14 16:00:01
20030000000018 C82V160901H4094 2017-12-14 15:36:37 2017-12-14 16:00:01
20030000000019 C82V160901H4092 2017-12-14 15:54:38 2017-12-14 16:00:01
20030000000020 C82V160901H4091 2017-12-14 15:57:34 2017-12-14 16:00:01
20030000000021 C82V160901H4090 2017-12-14 15:31:26 2017-12-14 16:00:01
20030000000022 C82V160901H4064 2017-12-14 15:36:08 2017-12-14 16:00:01
20030000000023 C82V160901H4061 2017-12-14 15:39:48 2017-12-14 16:00:01
20030000000024 C82V160901H4058 2017-12-14 15:30:24 2017-12-14 16:00:01
20030000000025 C82V160901H4057 2017-12-14 15:39:29 2017-12-14 16:00:01
20030000000026 C82V160901H4054 2017-12-14 15:39:30 2017-12-14 16:00:01
20030000000027 C82V160901H4052 2017-12-14 15:58:54 2017-12-14 16:00:01
20030000000028 C82V160901H4051 2017-12-14 15:56:36 2017-12-14 16:00:01
20030000000030 C82V160901H4047 2017-12-14 15:58:31 2017-12-14 16:00:01
20030000000031 C82V160901H4045 2017-12-14 15:57:34 2017-12-14 16:00:01
20030000000032 C82V160901H4042 2017-12-14 15:38:20 2017-12-14 16:00:01
20030000000033 C82V160901H4040 2017-12-14 15:37:49 2017-12-14 16:00:01
20030000000034 C82V160901H4039 2017-12-14 15:30:19 2017-12-14 16:00:01
20030000000035 C82V160901H4033 2017-12-14 15:48:53 2017-12-14 16:00:01
20030000000037 C82V160901H3680 2017-12-02 13:38:22 2017-12-14 16:00:01
20030000000038 C82V160901H3677 2017-12-14 15:54:45 2017-12-14 16:00:01
20030000000040 C82V160901H3674 2017-12-02 11:24:55 2017-12-14 16:00:01
20030000000041 C82V160901H3673 2017-12-14 15:52:20 2017-12-14 16:00:01
20030000000042 C82V160901H3672 2017-12-14 15:34:51 2017-12-14 16:00:01
20030000000043 C82V160901H3671 2017-12-14 15:55:36 2017-12-14 16:00:01
20030000000044 C82V160901H3670 2017-12-14 11:38:00 2017-12-14 16:00:01
20030000000045 C82V160901H3669 2017-11-05 14:47:07 2017-11-28 03:00:30
20030000000046 C82V160901H3668 2017-12-14 15:12:06 2017-12-14 16:00:01
20030000000048 C82V160901H3665 2017-12-14 15:41:57 2017-12-14 16:00:01
20030000000049 C82V160901H3664 2017-11-28 21:53:54 2017-12-14 16:00:01
20030000000050 C82V160901H3663 2017-12-08 13:05:11 2017-12-14 16:00:01
20030000000051 C82V160901H3662 2017-11-05 07:23:27 2017-11-28 03:00:30
20030000000052 C82V160901H3658 2017-11-01 13:31:18 2017-11-28 03:00:30
20030000000053 C82V160901H3656 2017-12-14 15:35:41 2017-12-14 16:00:01
20030000000055 C82V160901H3266 2017-12-14 15:48:05 2017-12-14 16:00:01
20030000000056 C82V160901H3263 2017-12-14 15:58:01 2017-12-14 16:00:01
20030000000057 C82V160901H3262 2017-12-14 15:58:20 2017-12-14 16:00:01
20030000000060 C82V160901H3259 2017-12-14 15:59:09 2017-12-14 16:00:01
20030000000061 C82V160901H4167 2017-12-14 15:45:29 2017-12-14 16:00:01
20030000000062 C82V160901H4166 2017-12-14 15:30:10 2017-12-14 16:00:01
20030000000063 C82V160901H4165 2017-12-14 15:56:23 2017-12-14 16:00:01
20030000000064 C82V160901H4164 2017-12-12 08:07:19 2017-12-14 16:00:01
20030000000065 C82V160901H4163 2017-12-14 15:45:09 2017-12-14 16:00:01
20030000000066 C82V160901H4162 2017-12-14 15:59:38 2017-12-14 16:00:01
20030000000067 C82V160901H4160 2017-12-14 15:48:30 2017-12-14 16:00:01
20030000000068 C82V160901H4159 2017-12-01 19:18:07 2017-12-14 16:00:01
20030000000069 C82V160901H4158 2017-12-14 15:56:56 2017-12-14 16:00:01
20030000000070 C82V160901H4157 2017-12-14 15:31:19 2017-12-14 16:00:01
20030000000071 C82V160901H4156 2017-12-13 22:32:00 2017-12-14 16:00:01
20030000000072 C82V160901H4155 2017-11-03 04:25:16 2017-11-28 03:00:30
20030000000073 C82V160901H4154 2017-11-23 16:27:06 2017-11-28 03:00:30
20030000000074 C82V160901H4153 2017-12-14 15:41:08 2017-12-14 16:00:01
20030000000075 C82V160901H4036 2017-12-14 15:58:32 2017-12-14 16:00:01
20030000000076 C82V160901H4035 2017-12-14 15:56:47 2017-12-14 16:00:01
20030000000077 C82V160901H3268 2017-12-14 15:55:20 2017-12-14 16:00:01
20030000000078 C82V160901H3265 2017-12-14 15:46:35 2017-12-14 16:00:01
20030000000079 C82V160901H4102 2017-12-14 15:59:18 2017-12-14 16:00:01
20030000000080 C82V160901H4100 2017-12-14 15:32:21 2017-12-14 16:00:01
20030000000084 C82V160901H3683 2017-12-14 15:49:23 2017-12-14 16:00:01
20030000000085 C82V160901H3681 2017-12-14 15:51:21 2017-12-14 16:00:01
20030000000086 C82V160901H3678 2017-12-14 15:53:50 2017-12-14 16:00:01
20030000000087 C82V160901H3666 2017-12-14 15:40:38 2017-12-14 16:00:01
20030000000088 C82V160901H3661 2017-12-14 15:58:55 2017-12-14 16:00:01
20030000000090 C82V160901H3659 2017-12-14 15:47:59 2017-12-14 16:00:01
20030000000091 C82V160901H3654 2017-10-31 20:13:09 2017-11-28 03:00:30

[2017-12-14 16:35:16]---错误case个数为1!
[2017-12-14 16:35:22]---Traceback (most recent call last):
  File "D:\Beop-OnlineTest\interfaceTest\base_case\Base024checkRealTimeforGuangming.py", line 65, in Test
    a.raiseError(self.error,self.testCaseID)
  File "D:\Beop-OnlineTest\interfaceTest\Methods\BeopTools.py", line 155, in raiseError
    assert 0,"\n".join(error)
AssertionError: 光明项目数据库表t_data_realtime_fridge中实时数据10分钟内没有更新，见下表：
20030000000001   C82V160901H4097   2017-11-06 20:21:20   2017-11-28 03:00:30
20030000000045   C82V160901H3669   2017-11-05 14:47:07   2017-11-28 03:00:30
20030000000051   C82V160901H3662   2017-11-05 07:23:27   2017-11-28 03:00:30
20030000000052   C82V160901H3658   2017-11-01 13:31:18   2017-11-28 03:00:30
20030000000072   C82V160901H4155   2017-11-03 04:25:16   2017-11-28 03:00:30
20030000000073   C82V160901H4154   2017-11-23 16:27:06   2017-11-28 03:00:30
20030000000091   C82V160901H3654   2017-10-31 20:13:09   2017-11-28 03:00:30

[2017-12-18 15:37:11]---错误case个数为1!
[2017-12-18 15:37:12]---Traceback (most recent call last):
  File "C:\Users\PC\AppData\Local\Programs\Python\Python35\lib\site-packages\pymysql\connections.py", line 890, in connect
    (self.host, self.port), self.connect_timeout)
  File "C:\Users\PC\AppData\Local\Programs\Python\Python35\lib\socket.py", line 711, in create_connection
    raise err
TimeoutError: [WinError 10060] 由于连接方在一段时间后没有正确答复或连接的主机没有反应，连接尝试失败。

During handling of the above exception, another exception occurred:

Traceback (most recent call last):
  File "D:\Beop-OnlineTest\interfaceTest\base_case\Base028mysqlValidata.py", line 74, in getMysqldata
    host=sqlip, db='diagnosis',charset='utf8',read_timeout = 20,connect_timeout=300)
  File "C:\Users\PC\AppData\Local\Programs\Python\Python35\lib\site-packages\pymysql\__init__.py", line 90, in Connect
    return Connection(*args, **kwargs)
pymysql.err.OperationalError: (2003, "Can't connect to MySQL server on 'rds8961fe732pz9uw7js.mysql.rds.aliyuncs.com' ([WinError 10060] 由于连接方在一段时间后没有正确答复或连接的主机没有反应，连接尝试失败。)")

During handling of the above exception, another exception occurred:

Traceback (most recent call last):
  File "D:\Beop-OnlineTest\interfaceTest\base_case\Base028mysqlValidata.py", line 37, in Test
    kk = self.getMysqldata(sql,list(ip.keys())[0],list(ip.values())[0][0],list(ip.values())[0][-1])
  File "D:\Beop-OnlineTest\interfaceTest\base_case\Base028mysqlValidata.py", line 80, in getMysqldata
    assert 0,"读取数据库%s数据错误信息为：%s"%(sqlip,e.__str__())
AssertionError: 读取数据库rds8961fe732pz9uw7js.mysql.rds.aliyuncs.com数据错误信息为：(2003, "Can't connect to MySQL server on 'rds8961fe732pz9uw7js.mysql.rds.aliyuncs.com' ([WinError 10060] 由于连接方在一段时间后没有正确答复或连接的主机没有反应，连接尝试失败。)")

[2017-12-18 15:40:13]---错误case个数为1!
[2017-12-18 15:40:13]---Traceback (most recent call last):
  File "C:\Users\PC\AppData\Local\Programs\Python\Python35\lib\site-packages\pymysql\connections.py", line 890, in connect
    (self.host, self.port), self.connect_timeout)
  File "C:\Users\PC\AppData\Local\Programs\Python\Python35\lib\socket.py", line 711, in create_connection
    raise err
TimeoutError: [WinError 10060] 由于连接方在一段时间后没有正确答复或连接的主机没有反应，连接尝试失败。

During handling of the above exception, another exception occurred:

Traceback (most recent call last):
  File "D:\Beop-OnlineTest\interfaceTest\base_case\Base028mysqlValidata.py", line 74, in getMysqldata
    host=sqlip, db='diagnosis',charset='utf8',read_timeout = 20,connect_timeout=300)
  File "C:\Users\PC\AppData\Local\Programs\Python\Python35\lib\site-packages\pymysql\__init__.py", line 90, in Connect
    return Connection(*args, **kwargs)
pymysql.err.OperationalError: (2003, "Can't connect to MySQL server on 'rds8961fe732pz9uw7js.mysql.rds.aliyuncs.com' ([WinError 10060] 由于连接方在一段时间后没有正确答复或连接的主机没有反应，连接尝试失败。)")

During handling of the above exception, another exception occurred:

Traceback (most recent call last):
  File "D:\Beop-OnlineTest\interfaceTest\base_case\Base028mysqlValidata.py", line 37, in Test
    kk = self.getMysqldata(sql,list(ip.keys())[0],list(ip.values())[0][0],list(ip.values())[0][-1])
  File "D:\Beop-OnlineTest\interfaceTest\base_case\Base028mysqlValidata.py", line 80, in getMysqldata
    assert 0,"读取数据库%s数据错误信息为：%s"%(sqlip,e.__str__())
AssertionError: 读取数据库rds8961fe732pz9uw7js.mysql.rds.aliyuncs.com数据错误信息为：(2003, "Can't connect to MySQL server on 'rds8961fe732pz9uw7js.mysql.rds.aliyuncs.com' ([WinError 10060] 由于连接方在一段时间后没有正确答复或连接的主机没有反应，连接尝试失败。)")

[2017-12-18 15:47:18]---错误case个数为1!
[2017-12-18 15:47:19]---Traceback (most recent call last):
  File "C:\Users\PC\AppData\Local\Programs\Python\Python35\lib\site-packages\pymysql\connections.py", line 890, in connect
    (self.host, self.port), self.connect_timeout)
  File "C:\Users\PC\AppData\Local\Programs\Python\Python35\lib\socket.py", line 711, in create_connection
    raise err
TimeoutError: [WinError 10060] 由于连接方在一段时间后没有正确答复或连接的主机没有反应，连接尝试失败。

During handling of the above exception, another exception occurred:

Traceback (most recent call last):
  File "D:\Beop-OnlineTest\interfaceTest\base_case\Base028mysqlValidata.py", line 74, in getMysqldata
    host=sqlip, db='diagnosis',charset='utf8',read_timeout = 20,connect_timeout=300)
  File "C:\Users\PC\AppData\Local\Programs\Python\Python35\lib\site-packages\pymysql\__init__.py", line 90, in Connect
    return Connection(*args, **kwargs)
pymysql.err.OperationalError: (2003, "Can't connect to MySQL server on 'rds8961fe732pz9uw7js.mysql.rds.aliyuncs.com' ([WinError 10060] 由于连接方在一段时间后没有正确答复或连接的主机没有反应，连接尝试失败。)")

During handling of the above exception, another exception occurred:

Traceback (most recent call last):
  File "D:\Beop-OnlineTest\interfaceTest\base_case\Base028mysqlValidata.py", line 37, in Test
    kk = self.getMysqldata(sql,list(ip.keys())[0],list(ip.values())[0][0],list(ip.values())[0][-1])
  File "D:\Beop-OnlineTest\interfaceTest\base_case\Base028mysqlValidata.py", line 80, in getMysqldata
    assert 0,"读取数据库%s数据错误信息为：%s"%(sqlip,e.__str__())
AssertionError: 读取数据库rds8961fe732pz9uw7js.mysql.rds.aliyuncs.com数据错误信息为：(2003, "Can't connect to MySQL server on 'rds8961fe732pz9uw7js.mysql.rds.aliyuncs.com' ([WinError 10060] 由于连接方在一段时间后没有正确答复或连接的主机没有反应，连接尝试失败。)")

[2017-12-18 15:47:35]---邮箱为空!
[2017-12-18 15:49:10]---错误case个数为1!
[2017-12-18 15:49:10]---Traceback (most recent call last):
  File "C:\Users\PC\AppData\Local\Programs\Python\Python35\lib\site-packages\pymysql\connections.py", line 890, in connect
    (self.host, self.port), self.connect_timeout)
  File "C:\Users\PC\AppData\Local\Programs\Python\Python35\lib\socket.py", line 711, in create_connection
    raise err
TimeoutError: [WinError 10060] 由于连接方在一段时间后没有正确答复或连接的主机没有反应，连接尝试失败。

During handling of the above exception, another exception occurred:

Traceback (most recent call last):
  File "D:\Beop-OnlineTest\interfaceTest\base_case\Base028mysqlValidata.py", line 74, in getMysqldata
    host=sqlip, db='diagnosis',charset='utf8',read_timeout = 20,connect_timeout=300)
  File "C:\Users\PC\AppData\Local\Programs\Python\Python35\lib\site-packages\pymysql\__init__.py", line 90, in Connect
    return Connection(*args, **kwargs)
pymysql.err.OperationalError: (2003, "Can't connect to MySQL server on 'rds8961fe732pz9uw7js.mysql.rds.aliyuncs.com' ([WinError 10060] 由于连接方在一段时间后没有正确答复或连接的主机没有反应，连接尝试失败。)")

During handling of the above exception, another exception occurred:

Traceback (most recent call last):
  File "D:\Beop-OnlineTest\interfaceTest\base_case\Base028mysqlValidata.py", line 37, in Test
    kk = self.getMysqldata(sql,list(ip.keys())[0],list(ip.values())[0][0],list(ip.values())[0][-1])
  File "D:\Beop-OnlineTest\interfaceTest\base_case\Base028mysqlValidata.py", line 80, in getMysqldata
    assert 0,"读取数据库%s数据错误信息为：%s"%(sqlip,e.__str__())
AssertionError: 读取数据库rds8961fe732pz9uw7js.mysql.rds.aliyuncs.com数据错误信息为：(2003, "Can't connect to MySQL server on 'rds8961fe732pz9uw7js.mysql.rds.aliyuncs.com' ([WinError 10060] 由于连接方在一段时间后没有正确答复或连接的主机没有反应，连接尝试失败。)")

[2017-12-18 15:55:15]---错误case个数为2!
[2017-12-18 15:55:15]---Traceback (most recent call last):
  File "C:\Users\PC\AppData\Local\Programs\Python\Python35\lib\site-packages\pymysql\connections.py", line 890, in connect
    (self.host, self.port), self.connect_timeout)
  File "C:\Users\PC\AppData\Local\Programs\Python\Python35\lib\socket.py", line 711, in create_connection
    raise err
TimeoutError: [WinError 10060] 由于连接方在一段时间后没有正确答复或连接的主机没有反应，连接尝试失败。

During handling of the above exception, another exception occurred:

Traceback (most recent call last):
  File "D:\Beop-OnlineTest\interfaceTest\base_case\Base028mysqlValidata.py", line 74, in getMysqldata
    host=sqlip, db='diagnosis',charset='utf8',read_timeout = 20,connect_timeout=300)
  File "C:\Users\PC\AppData\Local\Programs\Python\Python35\lib\site-packages\pymysql\__init__.py", line 90, in Connect
    return Connection(*args, **kwargs)
pymysql.err.OperationalError: (2003, "Can't connect to MySQL server on 'rds8961fe732pz9uw7js.mysql.rds.aliyuncs.com' ([WinError 10060] 由于连接方在一段时间后没有正确答复或连接的主机没有反应，连接尝试失败。)")

During handling of the above exception, another exception occurred:

Traceback (most recent call last):
  File "D:\Beop-OnlineTest\interfaceTest\base_case\Base028mysqlValidata.py", line 37, in Test
    kk = self.getMysqldata(sql,list(ip.keys())[0],list(ip.values())[0][0],list(ip.values())[0][-1])
  File "D:\Beop-OnlineTest\interfaceTest\base_case\Base028mysqlValidata.py", line 80, in getMysqldata
    assert 0,"读取数据库%s数据错误信息为：%s"%(sqlip,e.__str__())
AssertionError: 读取数据库rds8961fe732pz9uw7js.mysql.rds.aliyuncs.com数据错误信息为：(2003, "Can't connect to MySQL server on 'rds8961fe732pz9uw7js.mysql.rds.aliyuncs.com' ([WinError 10060] 由于连接方在一段时间后没有正确答复或连接的主机没有反应，连接尝试失败。)")

[2017-12-18 15:55:15]---邮箱为空!
[2017-12-18 15:55:15]---错误case个数为2!
[2017-12-18 15:55:15]---Traceback (most recent call last):
  File "D:\Beop-OnlineTest\interfaceTest\base_case\Base029mysqlforguangming.py", line 57, in Test
    self.a.raiseError(self.error,self.testCaseID)
  File "D:\Beop-OnlineTest\interfaceTest\Methods\BeopTools.py", line 155, in raiseError
    assert 0,"\n".join(error)
AssertionError: [68831, '青浦', '0.0', '2017-12-18 15:54:50', '温度', '℃', 1, '联机', '10.0', '-10.0', '航运新城块-航运新城冷库', '光明乳业', '航运新城块-航运新城冷库', '青浦', 1]
[68752, '中区', '0.0', '2017-12-18 15:54:50', '温度', '℃', 1, '联机', '10.0', '-10.0', '黄陂块-大沽冷库', '光明乳业', '黄陂块-大沽冷库', '中区', 1]
[68770, '中区', '10.8', '2017-12-18 15:54:50', '温度', '℃', 1, '联机', '10.0', '-10.0', '蒙西块-蒙西冷库', '光明乳业', '蒙西块-蒙西冷库', '中区', 1]
[69144, '中区', '0.0', '2017-12-18 15:54:50', '温度', '℃', 1, '联机', '10.0', '-10.0', '武定块-曹家冷库', '光明乳业', '武定块-曹家冷库', '中区', 1]
['中区', '黄陂块-大沽冷库', '2016-08-29 11:06:35']
['中区', '武定块-曹家冷库', '2017-05-11 13:17:25']
['中区', '淡水块-重庆冷库', '2017-12-18 08:07:08']
['青浦', '航运新城块-航运新城冷库', '2017-12-18 15:40:28']

[2017-12-18 15:55:16]---发送邮件成功!
[2017-12-18 15:59:17]---错误case个数为2!
[2017-12-18 15:59:17]---Traceback (most recent call last):
  File "C:\Users\PC\AppData\Local\Programs\Python\Python35\lib\site-packages\pymysql\connections.py", line 890, in connect
    (self.host, self.port), self.connect_timeout)
  File "C:\Users\PC\AppData\Local\Programs\Python\Python35\lib\socket.py", line 711, in create_connection
    raise err
TimeoutError: [WinError 10060] 由于连接方在一段时间后没有正确答复或连接的主机没有反应，连接尝试失败。

During handling of the above exception, another exception occurred:

Traceback (most recent call last):
  File "D:\Beop-OnlineTest\interfaceTest\base_case\Base028mysqlValidata.py", line 74, in getMysqldata
    host=sqlip, db='diagnosis',charset='utf8',read_timeout = 20,connect_timeout=300)
  File "C:\Users\PC\AppData\Local\Programs\Python\Python35\lib\site-packages\pymysql\__init__.py", line 90, in Connect
    return Connection(*args, **kwargs)
pymysql.err.OperationalError: (2003, "Can't connect to MySQL server on 'rds8961fe732pz9uw7js.mysql.rds.aliyuncs.com' ([WinError 10060] 由于连接方在一段时间后没有正确答复或连接的主机没有反应，连接尝试失败。)")

During handling of the above exception, another exception occurred:

Traceback (most recent call last):
  File "D:\Beop-OnlineTest\interfaceTest\base_case\Base028mysqlValidata.py", line 37, in Test
    kk = self.getMysqldata(sql,list(ip.keys())[0],list(ip.values())[0][0],list(ip.values())[0][-1])
  File "D:\Beop-OnlineTest\interfaceTest\base_case\Base028mysqlValidata.py", line 80, in getMysqldata
    assert 0,"读取数据库%s数据错误信息为：%s"%(sqlip,e.__str__())
AssertionError: 读取数据库rds8961fe732pz9uw7js.mysql.rds.aliyuncs.com数据错误信息为：(2003, "Can't connect to MySQL server on 'rds8961fe732pz9uw7js.mysql.rds.aliyuncs.com' ([WinError 10060] 由于连接方在一段时间后没有正确答复或连接的主机没有反应，连接尝试失败。)")

[2017-12-18 15:59:37]---邮箱为空!
[2017-12-18 15:59:40]---错误case个数为2!
[2017-12-18 15:59:40]---Traceback (most recent call last):
  File "D:\Beop-OnlineTest\interfaceTest\base_case\Base029mysqlforguangming.py", line 57, in Test
    self.a.raiseError(self.error,self.testCaseID)
  File "D:\Beop-OnlineTest\interfaceTest\Methods\BeopTools.py", line 155, in raiseError
    assert 0,"\n".join(error)
AssertionError: [68752, '中区', '0.0', '2017-12-18 15:57:48', '温度', '℃', 1, '联机', '10.0', '-10.0', '黄陂块-大沽冷库', '光明乳业', '黄陂块-大沽冷库', '中区', 1]
[68770, '中区', '10.8', '2017-12-18 15:57:48', '温度', '℃', 1, '联机', '10.0', '-10.0', '蒙西块-蒙西冷库', '光明乳业', '蒙西块-蒙西冷库', '中区', 1]
[69144, '中区', '0.0', '2017-12-18 15:57:48', '温度', '℃', 1, '联机', '10.0', '-10.0', '武定块-曹家冷库', '光明乳业', '武定块-曹家冷库', '中区', 1]
['中区', '黄陂块-大沽冷库', '2016-08-29 11:06:35']
['中区', '武定块-曹家冷库', '2017-05-11 13:17:25']
['青浦', '航运新城块-航运新城冷库', '2017-12-18 15:40:28']
['中区', '蒙西块-蒙西冷库', '2017-12-18 15:45:36']

[2017-12-18 16:17:22]---错误case个数为2!
[2017-12-18 16:17:22]---Traceback (most recent call last):
  File "C:\Users\PC\AppData\Local\Programs\Python\Python35\lib\site-packages\pymysql\connections.py", line 890, in connect
    (self.host, self.port), self.connect_timeout)
  File "C:\Users\PC\AppData\Local\Programs\Python\Python35\lib\socket.py", line 711, in create_connection
    raise err
TimeoutError: [WinError 10060] 由于连接方在一段时间后没有正确答复或连接的主机没有反应，连接尝试失败。

During handling of the above exception, another exception occurred:

Traceback (most recent call last):
  File "D:\Beop-OnlineTest\interfaceTest\base_case\Base028mysqlValidata.py", line 74, in getMysqldata
    host=sqlip, db='diagnosis',charset='utf8',read_timeout = 20,connect_timeout=300)
  File "C:\Users\PC\AppData\Local\Programs\Python\Python35\lib\site-packages\pymysql\__init__.py", line 90, in Connect
    return Connection(*args, **kwargs)
pymysql.err.OperationalError: (2003, "Can't connect to MySQL server on 'rds8961fe732pz9uw7js.mysql.rds.aliyuncs.com' ([WinError 10060] 由于连接方在一段时间后没有正确答复或连接的主机没有反应，连接尝试失败。)")

During handling of the above exception, another exception occurred:

Traceback (most recent call last):
  File "D:\Beop-OnlineTest\interfaceTest\base_case\Base028mysqlValidata.py", line 37, in Test
    kk = self.getMysqldata(sql,list(ip.keys())[0],list(ip.values())[0][0],list(ip.values())[0][-1])
  File "D:\Beop-OnlineTest\interfaceTest\base_case\Base028mysqlValidata.py", line 80, in getMysqldata
    assert 0,"读取数据库%s数据错误信息为：%s"%(sqlip,e.__str__())
AssertionError: 读取数据库rds8961fe732pz9uw7js.mysql.rds.aliyuncs.com数据错误信息为：(2003, "Can't connect to MySQL server on 'rds8961fe732pz9uw7js.mysql.rds.aliyuncs.com' ([WinError 10060] 由于连接方在一段时间后没有正确答复或连接的主机没有反应，连接尝试失败。)")

[2017-12-18 16:17:27]---邮箱为空!
[2017-12-18 16:17:29]---错误case个数为2!
[2017-12-18 16:17:29]---Traceback (most recent call last):
  File "D:\Beop-OnlineTest\interfaceTest\base_case\Base029mysqlforguangming.py", line 57, in Test
    self.a.raiseError(self.error[0],self.testCaseID)
  File "D:\Beop-OnlineTest\interfaceTest\Methods\BeopTools.py", line 155, in raiseError
    assert 0,"\n".join(error)
AssertionError: [68752, '中区', '0.0', '2017-12-18 16:16:49', '温度', '℃', 1, '联机', '10.0', '-10.0', '黄陂块-大沽冷库', '光明乳业', '黄陂块-大沽冷库', '中区', 1]
[69144, '中区', '0.0', '2017-12-18 16:16:49', '温度', '℃', 1, '联机', '10.0', '-10.0', '武定块-曹家冷库', '光明乳业', '武定块-曹家冷库', '中区', 1]
['中区', '黄陂块-大沽冷库', '2016-08-29 11:06:35']
['中区', '武定块-曹家冷库', '2017-05-11 13:17:25']

[2017-12-18 16:19:18]---错误case个数为2!
[2017-12-18 16:19:18]---Traceback (most recent call last):
  File "C:\Users\PC\AppData\Local\Programs\Python\Python35\lib\site-packages\pymysql\connections.py", line 890, in connect
    (self.host, self.port), self.connect_timeout)
  File "C:\Users\PC\AppData\Local\Programs\Python\Python35\lib\socket.py", line 711, in create_connection
    raise err
TimeoutError: [WinError 10060] 由于连接方在一段时间后没有正确答复或连接的主机没有反应，连接尝试失败。

During handling of the above exception, another exception occurred:

Traceback (most recent call last):
  File "D:\Beop-OnlineTest\interfaceTest\base_case\Base028mysqlValidata.py", line 74, in getMysqldata
    host=sqlip, db='diagnosis',charset='utf8',read_timeout = 20,connect_timeout=300)
  File "C:\Users\PC\AppData\Local\Programs\Python\Python35\lib\site-packages\pymysql\__init__.py", line 90, in Connect
    return Connection(*args, **kwargs)
pymysql.err.OperationalError: (2003, "Can't connect to MySQL server on 'rds8961fe732pz9uw7js.mysql.rds.aliyuncs.com' ([WinError 10060] 由于连接方在一段时间后没有正确答复或连接的主机没有反应，连接尝试失败。)")

During handling of the above exception, another exception occurred:

Traceback (most recent call last):
  File "D:\Beop-OnlineTest\interfaceTest\base_case\Base028mysqlValidata.py", line 37, in Test
    kk = self.getMysqldata(sql,list(ip.keys())[0],list(ip.values())[0][0],list(ip.values())[0][-1])
  File "D:\Beop-OnlineTest\interfaceTest\base_case\Base028mysqlValidata.py", line 80, in getMysqldata
    assert 0,"读取数据库%s数据错误信息为：%s"%(sqlip,e.__str__())
AssertionError: 读取数据库rds8961fe732pz9uw7js.mysql.rds.aliyuncs.com数据错误信息为：(2003, "Can't connect to MySQL server on 'rds8961fe732pz9uw7js.mysql.rds.aliyuncs.com' ([WinError 10060] 由于连接方在一段时间后没有正确答复或连接的主机没有反应，连接尝试失败。)")

[2017-12-18 16:19:24]---邮箱为空!
[2017-12-18 16:19:25]---错误case个数为2!
[2017-12-18 16:19:26]---Traceback (most recent call last):
  File "D:\Beop-OnlineTest\interfaceTest\base_case\Base029mysqlforguangming.py", line 57, in Test
    self.a.raiseError(self.error[0],self.testCaseID)
  File "D:\Beop-OnlineTest\interfaceTest\Methods\BeopTools.py", line 155, in raiseError
    assert 0,"\n".join(error)
AssertionError: [68752, '中区', '0.0', '2017-12-18 16:18:51', '温度', '℃', 1, '联机', '10.0', '-10.0', '黄陂块-大沽冷库', '光明乳业', '黄陂块-大沽冷库', '中区', 1]
[69144, '中区', '0.0', '2017-12-18 16:18:44', '温度', '℃', 1, '联机', '10.0', '-10.0', '武定块-曹家冷库', '光明乳业', '武定块-曹家冷库', '中区', 1]
['中区', '黄陂块-大沽冷库', '2016-08-29 11:06:35']
['中区', '武定块-曹家冷库', '2017-05-11 13:17:25']

[2017-12-18 16:40:30]---错误case个数为1!
[2017-12-18 16:40:30]---Traceback (most recent call last):
  File "C:\Users\PC\AppData\Local\Programs\Python\Python35\lib\site-packages\pymysql\connections.py", line 890, in connect
    (self.host, self.port), self.connect_timeout)
  File "C:\Users\PC\AppData\Local\Programs\Python\Python35\lib\socket.py", line 711, in create_connection
    raise err
TimeoutError: [WinError 10060] 由于连接方在一段时间后没有正确答复或连接的主机没有反应，连接尝试失败。

During handling of the above exception, another exception occurred:

Traceback (most recent call last):
  File "D:\Beop-OnlineTest\interfaceTest\base_case\Base028mysqlValidata.py", line 74, in getMysqldata
    host=sqlip, db='diagnosis',charset='utf8',read_timeout = 20,connect_timeout=300)
  File "C:\Users\PC\AppData\Local\Programs\Python\Python35\lib\site-packages\pymysql\__init__.py", line 90, in Connect
    return Connection(*args, **kwargs)
pymysql.err.OperationalError: (2003, "Can't connect to MySQL server on 'rds8961fe732pz9uw7js.mysql.rds.aliyuncs.com' ([WinError 10060] 由于连接方在一段时间后没有正确答复或连接的主机没有反应，连接尝试失败。)")

During handling of the above exception, another exception occurred:

Traceback (most recent call last):
  File "D:\Beop-OnlineTest\interfaceTest\base_case\Base028mysqlValidata.py", line 37, in Test
    kk = self.getMysqldata(sql,list(ip.keys())[0],list(ip.values())[0][0],list(ip.values())[0][-1])
  File "D:\Beop-OnlineTest\interfaceTest\base_case\Base028mysqlValidata.py", line 80, in getMysqldata
    assert 0,"读取数据库%s数据错误信息为：%s"%(sqlip,e.__str__())
AssertionError: 读取数据库rds8961fe732pz9uw7js.mysql.rds.aliyuncs.com数据错误信息为：(2003, "Can't connect to MySQL server on 'rds8961fe732pz9uw7js.mysql.rds.aliyuncs.com' ([WinError 10060] 由于连接方在一段时间后没有正确答复或连接的主机没有反应，连接尝试失败。)")

[2017-12-18 16:40:30]---邮箱为空!
[2017-12-18 16:41:42]---错误case个数为1!
[2017-12-18 16:41:42]---Traceback (most recent call last):
  File "C:\Users\PC\AppData\Local\Programs\Python\Python35\lib\site-packages\pymysql\connections.py", line 890, in connect
    (self.host, self.port), self.connect_timeout)
  File "C:\Users\PC\AppData\Local\Programs\Python\Python35\lib\socket.py", line 711, in create_connection
    raise err
TimeoutError: [WinError 10060] 由于连接方在一段时间后没有正确答复或连接的主机没有反应，连接尝试失败。

During handling of the above exception, another exception occurred:

Traceback (most recent call last):
  File "D:\Beop-OnlineTest\interfaceTest\base_case\Base028mysqlValidata.py", line 74, in getMysqldata
    host=sqlip, db='diagnosis',charset='utf8',read_timeout = 20,connect_timeout=300)
  File "C:\Users\PC\AppData\Local\Programs\Python\Python35\lib\site-packages\pymysql\__init__.py", line 90, in Connect
    return Connection(*args, **kwargs)
pymysql.err.OperationalError: (2003, "Can't connect to MySQL server on 'rds8961fe732pz9uw7js.mysql.rds.aliyuncs.com' ([WinError 10060] 由于连接方在一段时间后没有正确答复或连接的主机没有反应，连接尝试失败。)")

During handling of the above exception, another exception occurred:

Traceback (most recent call last):
  File "D:\Beop-OnlineTest\interfaceTest\base_case\Base028mysqlValidata.py", line 37, in Test
    kk = self.getMysqldata(sql,list(ip.keys())[0],list(ip.values())[0][0],list(ip.values())[0][-1])
  File "D:\Beop-OnlineTest\interfaceTest\base_case\Base028mysqlValidata.py", line 80, in getMysqldata
    assert 0,"读取数据库%s数据错误信息为：%s"%(sqlip,e.__str__())
AssertionError: 读取数据库rds8961fe732pz9uw7js.mysql.rds.aliyuncs.com数据错误信息为：(2003, "Can't connect to MySQL server on 'rds8961fe732pz9uw7js.mysql.rds.aliyuncs.com' ([WinError 10060] 由于连接方在一段时间后没有正确答复或连接的主机没有反应，连接尝试失败。)")

[2017-12-18 16:41:42]---邮箱为空!
[2017-12-18 16:45:54]---错误case个数为1!
[2017-12-18 16:45:54]---Traceback (most recent call last):
  File "C:\Users\PC\AppData\Local\Programs\Python\Python35\lib\site-packages\pymysql\connections.py", line 890, in connect
    (self.host, self.port), self.connect_timeout)
  File "C:\Users\PC\AppData\Local\Programs\Python\Python35\lib\socket.py", line 711, in create_connection
    raise err
TimeoutError: [WinError 10060] 由于连接方在一段时间后没有正确答复或连接的主机没有反应，连接尝试失败。

During handling of the above exception, another exception occurred:

Traceback (most recent call last):
  File "D:\Beop-OnlineTest\interfaceTest\base_case\Base028mysqlValidata.py", line 74, in getMysqldata
    host=sqlip, db='diagnosis',charset='utf8',read_timeout = 20,connect_timeout=300)
  File "C:\Users\PC\AppData\Local\Programs\Python\Python35\lib\site-packages\pymysql\__init__.py", line 90, in Connect
    return Connection(*args, **kwargs)
pymysql.err.OperationalError: (2003, "Can't connect to MySQL server on 'rds8961fe732pz9uw7js.mysql.rds.aliyuncs.com' ([WinError 10060] 由于连接方在一段时间后没有正确答复或连接的主机没有反应，连接尝试失败。)")

During handling of the above exception, another exception occurred:

Traceback (most recent call last):
  File "D:\Beop-OnlineTest\interfaceTest\base_case\Base028mysqlValidata.py", line 37, in Test
    kk = self.getMysqldata(sql,list(ip.keys())[0],list(ip.values())[0][0],list(ip.values())[0][-1])
  File "D:\Beop-OnlineTest\interfaceTest\base_case\Base028mysqlValidata.py", line 80, in getMysqldata
    assert 0,"读取数据库%s数据错误信息为：%s"%(sqlip,e.__str__())
AssertionError: 读取数据库rds8961fe732pz9uw7js.mysql.rds.aliyuncs.com数据错误信息为：(2003, "Can't connect to MySQL server on 'rds8961fe732pz9uw7js.mysql.rds.aliyuncs.com' ([WinError 10060] 由于连接方在一段时间后没有正确答复或连接的主机没有反应，连接尝试失败。)")

[2017-12-18 16:45:59]---邮箱为空!
[2017-12-18 16:47:36]---错误case个数为1!
[2017-12-18 16:47:36]---Traceback (most recent call last):
  File "C:\Users\PC\AppData\Local\Programs\Python\Python35\lib\site-packages\pymysql\connections.py", line 890, in connect
    (self.host, self.port), self.connect_timeout)
  File "C:\Users\PC\AppData\Local\Programs\Python\Python35\lib\socket.py", line 711, in create_connection
    raise err
TimeoutError: [WinError 10060] 由于连接方在一段时间后没有正确答复或连接的主机没有反应，连接尝试失败。

During handling of the above exception, another exception occurred:

Traceback (most recent call last):
  File "D:\Beop-OnlineTest\interfaceTest\base_case\Base028mysqlValidata.py", line 74, in getMysqldata
    host=sqlip, db='diagnosis',charset='utf8',read_timeout = 20,connect_timeout=300)
  File "C:\Users\PC\AppData\Local\Programs\Python\Python35\lib\site-packages\pymysql\__init__.py", line 90, in Connect
    return Connection(*args, **kwargs)
pymysql.err.OperationalError: (2003, "Can't connect to MySQL server on 'rds8961fe732pz9uw7js.mysql.rds.aliyuncs.com' ([WinError 10060] 由于连接方在一段时间后没有正确答复或连接的主机没有反应，连接尝试失败。)")

During handling of the above exception, another exception occurred:

Traceback (most recent call last):
  File "D:\Beop-OnlineTest\interfaceTest\base_case\Base028mysqlValidata.py", line 37, in Test
    kk = self.getMysqldata(sql,list(ip.keys())[0],list(ip.values())[0][0],list(ip.values())[0][-1])
  File "D:\Beop-OnlineTest\interfaceTest\base_case\Base028mysqlValidata.py", line 80, in getMysqldata
    assert 0,"读取数据库%s数据错误信息为：%s"%(sqlip,e.__str__())
AssertionError: 读取数据库rds8961fe732pz9uw7js.mysql.rds.aliyuncs.com数据错误信息为：(2003, "Can't connect to MySQL server on 'rds8961fe732pz9uw7js.mysql.rds.aliyuncs.com' ([WinError 10060] 由于连接方在一段时间后没有正确答复或连接的主机没有反应，连接尝试失败。)")

[2017-12-18 16:49:40]---错误case个数为1!
[2017-12-18 16:49:40]---Traceback (most recent call last):
  File "D:\Beop-OnlineTest\interfaceTest\base_case\Base029mysqlforguangming.py", line 57, in Test
    self.a.raiseError(self.error,self.testCaseID)
  File "D:\Beop-OnlineTest\interfaceTest\Methods\BeopTools.py", line 155, in raiseError
    assert 0,"\n".join(error)
AssertionError: [68752, '中区', '0.0', '2017-12-18 16:49:23', '温度', '℃', 1, '联机', '10.0', '-10.0', '黄陂块-大沽冷库', '光明乳业', '黄陂块-大沽冷库', '中区', 1]
[68791, '中区', '0.0', '2017-12-18 16:49:23', '温度', '℃', 1, '联机', '10.0', '-10.0', '淡水块-重庆冷库', '光明乳业', '淡水块-重庆冷库', '中区', 1]
[69144, '中区', '0.0', '2017-12-18 16:49:23', '温度', '℃', 1, '联机', '10.0', '-10.0', '武定块-曹家冷库', '光明乳业', '武定块-曹家冷库', '中区', 1]
['中区', '黄陂块-大沽冷库', '2016-08-29 11:06:35']
['中区', '武定块-曹家冷库', '2017-05-11 13:17:25']
['中区', '淡水块-重庆冷库', '2017-12-18 16:36:06']

[2017-12-18 17:04:09]---错误case个数为1!
[2017-12-18 17:04:09]---Traceback (most recent call last):
  File "D:\Beop-OnlineTest\interfaceTest\base_case\Base029mysqlforguangming.py", line 57, in Test
    self.a.raiseError(self.error,self.testCaseID)
  File "D:\Beop-OnlineTest\interfaceTest\Methods\BeopTools.py", line 155, in raiseError
    assert 0,"\n".join(error)
AssertionError: [68752, '中区', '0.0', '2017-12-18 17:04:03', '温度', '℃', 1, '联机', '10.0', '-10.0', '黄陂块-大沽冷库', '光明乳业', '黄陂块-大沽冷库', '中区', 1]
[68791, '中区', '0.0', '2017-12-18 17:04:03', '温度', '℃', 1, '联机', '10.0', '-10.0', '淡水块-重庆冷库', '光明乳业', '淡水块-重庆冷库', '中区', 1]
[69144, '中区', '0.0', '2017-12-18 17:03:56', '温度', '℃', 1, '联机', '10.0', '-10.0', '武定块-曹家冷库', '光明乳业', '武定块-曹家冷库', '中区', 1]
['中区', '黄陂块-大沽冷库', '2016-08-29 11:06:35']
['中区', '武定块-曹家冷库', '2017-05-11 13:17:25']
['中区', '淡水块-重庆冷库', '2017-12-18 16:36:06']

[2017-12-18 18:26:09]---错误case个数为1!
[2017-12-18 18:26:09]---Traceback (most recent call last):
  File "D:\Beop-OnlineTest\interfaceTest\base_case\Base029mysqlforguangming.py", line 66, in Test
    self.a.raiseError(self.error,self.testCaseID)
  File "D:\Beop-OnlineTest\interfaceTest\Methods\BeopTools.py", line 155, in raiseError
    assert 0,"\n".join(error)
AssertionError: 实时数据未及时更新[68752, '中区', '0.0', '2017-12-18 18:25:11', '温度', '℃', 1, '联机', '10.0', '-10.0', '黄陂块-大沽冷库', '光明乳业', '黄陂块-大沽冷库', '中区', 1, 69144, '中区', '0.0', '2017-12-18 18:25:11', '温度', '℃', 1, '联机', '10.0', '-10.0', '武定块-曹家冷库', '光明乳业', '武定块-曹家冷库', '中区', 1]
[68752, '中区', '0.0', '2017-12-18 18:25:11', '温度', '℃', 1, '联机', '10.0', '-10.0', '黄陂块-大沽冷库', '光明乳业', '黄陂块-大沽冷库', '中区', 1, 69144, '中区', '0.0', '2017-12-18 18:25:11', '温度', '℃', 1, '联机', '10.0', '-10.0', '武定块-曹家冷库', '光明乳业', '武定块-曹家冷库', '中区', 1]
历史数据未及时更新['中区', '黄陂块-大沽冷库', '2016-08-29 11:06:35', '中区', '武定块-曹家冷库', '2017-05-11 13:17:25']
['中区', '黄陂块-大沽冷库', '2016-08-29 11:06:35', '中区', '武定块-曹家冷库', '2017-05-11 13:17:25']

[2017-12-18 18:27:27]---错误case个数为1!
[2017-12-18 18:27:27]---Traceback (most recent call last):
  File "D:\Beop-OnlineTest\interfaceTest\base_case\Base029mysqlforguangming.py", line 66, in Test
    self.a.raiseError(self.error,self.testCaseID)
  File "D:\Beop-OnlineTest\interfaceTest\Methods\BeopTools.py", line 155, in raiseError
    assert 0,"\n".join(error)
AssertionError: 实时数据未及时更新
[68752, '中区', '0.0', '2017-12-18 18:27:13', '温度', '℃', 1, '联机', '10.0', '-10.0', '黄陂块-大沽冷库', '光明乳业', '黄陂块-大沽冷库', '中区', 1, 69144, '中区', '0.0', '2017-12-18 18:27:13', '温度', '℃', 1, '联机', '10.0', '-10.0', '武定块-曹家冷库', '光明乳业', '武定块-曹家冷库', '中区', 1]
[68752, '中区', '0.0', '2017-12-18 18:27:13', '温度', '℃', 1, '联机', '10.0', '-10.0', '黄陂块-大沽冷库', '光明乳业', '黄陂块-大沽冷库', '中区', 1, 69144, '中区', '0.0', '2017-12-18 18:27:13', '温度', '℃', 1, '联机', '10.0', '-10.0', '武定块-曹家冷库', '光明乳业', '武定块-曹家冷库', '中区', 1]
历史数据未及时更新
['中区', '黄陂块-大沽冷库', '2016-08-29 11:06:35', '中区', '武定块-曹家冷库', '2017-05-11 13:17:25']
['中区', '黄陂块-大沽冷库', '2016-08-29 11:06:35', '中区', '武定块-曹家冷库', '2017-05-11 13:17:25']

[2017-12-27 16:41:25]---错误case个数为2!
[2017-12-27 16:41:26]---Traceback (most recent call last):
  File "D:\Beop-OnlineTest\interfaceTest\calcPoint_Case\Calc028checkPointIsNoneForAllProject.py", line 38, in Test
    self.a.raiseError(self.error, self.testCaseID)
  File "D:\Beop-OnlineTest\interfaceTest\Methods\BeopTools.py", line 155, in raiseError
    assert 0,"\n".join(error)
AssertionError: 错误信息华东电网调度中心大楼项目中的点有空值:
KPI_ProjTotal_ScoreMonth
KPI_Plant_M_Score
KPI_B3F_Plant_M_Score
KPI_6F_Plant_M_Score
KPI_RF_Plant_M_Score
LQT_RTemp_CV_MA_Score
B3F_CHW_DT_MA_Score
B3F_CHW_SupplyT_MA_Score
i6F_CHW_DT_MA_Score
i6F_CHW_SupplyP_MA_Score
i6F_CHW_SupplyT_MA_Score
RF_CHW_DT_MA_Score
RF_CHW_SupplyP_MA_Score
RF_CHW_SupplyT_MA_Score
LQT_RTemp_CV_MA
B3F_CHW_DT_MA
B3F_CHW_SupplyT_MA
i6F_CHW_DT_MA
i6F_CHW_SupplyP_MA
i6F_CHW_SupplyT_MA
RF_CHW_DT_MA
RF_CHW_SupplyP_MA
RF_CHW_SupplyT_MA

[2017-12-27 17:10:27]---错误case个数为2!
[2017-12-27 17:10:27]---Traceback (most recent call last):
  File "D:\Beop-OnlineTest\interfaceTest\calcPoint_Case\Calc028checkPointIsNoneForAllProject.py", line 38, in Test
    self.a.raiseError(self.error, self.testCaseID)
  File "D:\Beop-OnlineTest\interfaceTest\Methods\BeopTools.py", line 155, in raiseError
    assert 0,"\n".join(error)
AssertionError: 错误信息华东电网调度中心大楼项目中的点有空值:
KPI_ProjTotal_ScoreMonth
KPI_Plant_M_Score
KPI_B3F_Plant_M_Score
KPI_6F_Plant_M_Score
KPI_RF_Plant_M_Score
LQT_RTemp_CV_MA_Score
B3F_CHW_DT_MA_Score
B3F_CHW_SupplyT_MA_Score
i6F_CHW_DT_MA_Score
i6F_CHW_SupplyP_MA_Score
i6F_CHW_SupplyT_MA_Score
RF_CHW_DT_MA_Score
RF_CHW_SupplyP_MA_Score
RF_CHW_SupplyT_MA_Score
LQT_RTemp_CV_MA
B3F_CHW_DT_MA
B3F_CHW_SupplyT_MA
i6F_CHW_DT_MA
i6F_CHW_SupplyP_MA
i6F_CHW_SupplyT_MA
RF_CHW_DT_MA
RF_CHW_SupplyP_MA
RF_CHW_SupplyT_MA

[2017-12-27 17:14:20]---错误case个数为2!
[2017-12-27 17:14:20]---Traceback (most recent call last):
  File "D:\Beop-OnlineTest\interfaceTest\calcPoint_Case\Calc028checkPointIsNoneForAllProject.py", line 38, in Test
    self.a.raiseError(self.error, self.testCaseID)
  File "D:\Beop-OnlineTest\interfaceTest\Methods\BeopTools.py", line 155, in raiseError
    assert 0,"\n".join(error)
AssertionError: 错误信息华东电网调度中心大楼项目中的点有空值:
KPI_ProjTotal_ScoreMonth
KPI_Plant_M_Score
KPI_B3F_Plant_M_Score
KPI_6F_Plant_M_Score
KPI_RF_Plant_M_Score
LQT_RTemp_CV_MA_Score
B3F_CHW_DT_MA_Score
B3F_CHW_SupplyT_MA_Score
i6F_CHW_DT_MA_Score
i6F_CHW_SupplyP_MA_Score
i6F_CHW_SupplyT_MA_Score
RF_CHW_DT_MA_Score
RF_CHW_SupplyP_MA_Score
RF_CHW_SupplyT_MA_Score
LQT_RTemp_CV_MA
B3F_CHW_DT_MA
B3F_CHW_SupplyT_MA
i6F_CHW_DT_MA
i6F_CHW_SupplyP_MA
i6F_CHW_SupplyT_MA
RF_CHW_DT_MA
RF_CHW_SupplyP_MA
RF_CHW_SupplyT_MA

[2017-12-27 17:14:33]---邮箱为空!
[2017-12-27 17:14:34]---错误case个数为2!
[2017-12-27 17:14:34]---Traceback (most recent call last):
  File "D:\Beop-OnlineTest\interfaceTest\calcPoint_Case\Calc041greenslopesCal.py", line 33, in Test
    BeopTools.raiseError(self.errors, self.testCaseID)
  File "D:\Beop-OnlineTest\interfaceTest\Methods\BeopTools.py", line 155, in raiseError
    assert 0,"\n".join(error)
AssertionError: 错误信息Accum_ChGroup_GroupEnergy点在2017-12-27 16:00:00~2017-12-27 17:00:00点值发生突变或者一直没有递增!
错误信息Accum_CTFanGroup_GroupEnergy点在2017-12-27 16:00:00~2017-12-27 17:00:00点值发生突变或者一直没有递增!
错误信息Accum_CWPGroup_GroupEnergy点在2017-12-27 16:00:00~2017-12-27 17:00:00点值发生突变或者一直没有递增!
错误信息Accum_SCHWPGroup_GroupEnergy点在2017-12-27 16:00:00~2017-12-27 17:00:00点值发生突变或者一直没有递增!
错误信息Accum_PCHWPGroup_GroupEnergy点在2017-12-27 16:00:00~2017-12-27 17:00:00点值发生突变或者一直没有递增!

[2017-12-29 10:34:36]---错误case个数为1!
[2017-12-29 10:34:36]---Traceback (most recent call last):
  File "D:\Beop-OnlineTest\interfaceTest\calcPoint_Case\Calc028checkPointIsNoneForAllProject.py", line 38, in Test
    self.a.raiseError(self.error, self.testCaseID)
  File "D:\Beop-OnlineTest\interfaceTest\Methods\BeopTools.py", line 155, in raiseError
    assert 0,"\n".join(error)
AssertionError: 错误信息上海华为项目中的点有空值:
OutTempmy
错误信息香港华润项目中的点有空值:
Ch001_GroupElecUseD
Plant001_GroupElecUseD
Accum_CHWP011_ElecUseW
Accum_Ch007_ElecUseW
Accum_Ch006_ElecUseW
Accum_Ch005_ElecUseW
Accum_Ch004_ElecUseW
Accum_Ch003_ElecUseW
Accum_Ch002_ElecUseW
Accum_Ch001_ElecUseW
Accum_CHWP011_ElecUseD
Accum_Ch007_ElecUseD
Accum_Ch006_ElecUseD
Accum_Ch005_ElecUseD
Accum_Ch004_ElecUseD
Accum_Ch003_ElecUseD
Accum_Ch002_ElecUseD
Accum_Ch001_ElecUseD

